Workbook
Name _71_Temp: #REF!
Name _71_Temp: #REF!
Name _71_Temp: #REF!
Name _72_Temp: #REF!
Name _72_Temp: #REF!
Name _72_Temp: #REF!
Name Area_a_imprimir: #REF!
Name Area_a_imprimir: #REF!
Name Area_a_imprimir: #REF!
Name Area_de_impresión: #REF!
Name Area_de_impresión: #REF!
Name Area_de_impresión: #REF!
Name comg: #REF!
Name comg: #REF!
Name comg: #REF!
Name d: #REF!
Name d: #REF!
Name d: #REF!
Name ff: #REF!
Name ff: #REF!
Name ff: #REF!
Name P1D: #REF!
Name P1D: #REF!
Name P1D: #REF!
Name P1G: #REF!
Name P1G: #REF!
Name P1G: #REF!
Name Pág.1: #REF!
Name Pág.1: #REF!
Name Pág.1: #REF!
Name Pág.2: #REF!
Name Pág.2: #REF!
Name Pág.2: #REF!
Name Pág.3: #REF!
Name Pág.3: #REF!
Name Pág.3: #REF!
Name Pág.4: #REF!
Name Pág.4: #REF!
Name Pág.4: #REF!
Name Pág.5: #REF!
Name Pág.5: #REF!
Name Pág.5: #REF!
Name Pág.6: #REF!
Name Pág.6: #REF!
Name Pág.6: #REF!
Name Publicación: #REF!
Name Publicación: #REF!
Name Publicación: #REF!
Name SAM: #REF!
Name SAM: #REF!
Name SAM: #REF!
Name SAM_4x4: #REF!
Name SAM_4x4: #REF!
Name SAM_4x4: #REF!
Name SAMR: #REF!
Name SAMR: #REF!
Name SAMR: #REF!

Sheet Datos Originales
B2: Matriz de insumo-producto
B3: Doméstica a precio básico, actividad por actividad
B4: Supuesto: estructura de ventas fija por producto
B5: (miles de millones de pesos de 2022)
B8: Actividad | R8: Consumo de hogares | T8: Consumo de IPSFL | V8: Consumo de gobierno | X8: Formación bruta de capital fijo | Z8: Variación de existencias | AB8: Exportaciones | AD8: Producción precio básico
C9: 1 | D9: 2 | E9: 3 | F9: 4 | G9: 5 | H9: 6 | I9: 7 | J9: 8 | K9: 9 | L9: 10 | M9: 11 | N9: 12 | P9: Total
B12: 1 | C12: 4115.2532 | D12: 0.64223707 | E12: 11866.039 | F12: 41.40853 | G12: 13.540523 | H12: 323.50973 | I12: 3.71898 | J12: 1.17387 | K12: 0.046620561 | L12: 6.0921412 | M12: 59.351153 | N12: 62.713022 | P12: 16493.489 | R12: 2783.6759 | T12: 0 | V12: 0.02668751 | X12: 790.68687 | Z12: -133.35792 | AB12: 3460.4746 | AD12: 23394.995
B13: 2 | C13: 17.284375 | D13: 5176.8488 | E13: 3249.0835 | F13: 69.390609 | G13: 194.00931 | H13: 47.012199 | I13: 26.834354 | J13: 26.634541 | K13: 5.9874064 | L13: 48.327516 | M13: 28.725165 | N13: 9.6188119 | P13: 8899.7567 | R13: 46.319553 | T13: 0 | V13: 2.7228123 | X13: 704.96651 | Z13: -315.19166 | AB13: 50201.315 | AD13: 59539.889
B14: 3 | C14: 4649.3296 | D14: 3599.6667 | E14: 12335.839 | F14: 629.30829 | G14: 6599.0789 | H14: 4798.4364 | I14: 2849.6015 | J14: 175.11488 | K14: 62.121384 | L14: 724.34216 | M14: 2143.2518 | N14: 363.03963 | P14: 38929.131 | R14: 22272.496 | T14: 0 | V14: 86.443491 | X14: 4045.8566 | Z14: -300.63449 | AB14: 27660.472 | AD14: 92693.764
B15: 4 | C15: 245.39146 | D15: 3380.9071 | E15: 2940.4899 | F15: 2005.3179 | G15: 268.21389 | H15: 987.68204 | I15: 498.25205 | J15: 134.92253 | K15: 217.21723 | L15: 231.67899 | M15: 487.05718 | N15: 578.82228 | P15: 11975.953 | R15: 3763.8962 | T15: 0 | V15: 83.189665 | X15: 55.968354 | Z15: 0.45411781 | AB15: 81.48139 | AD15: 15960.942
B16: 5 | C16: 1.0332716 | D16: 3.0356266 | E16: 10.808026 | F16: 1.6691959 | G16: 5292.5471 | H16: 59.406448 | I16: 30.303137 | J16: 15.079325 | K16: 2916.6355 | L16: 17.996333 | M16: 20.730085 | N16: 5.9405624 | P16: 8375.1846 | R16: 11.802968 | T16: 0 | V16: 0.12944474 | X16: 28753.103 | Z16: 0 | AB16: 5.6507348 | AD16: 37145.871
B17: 6 | C17: 966.82834 | D17: 1770.7817 | E17: 4469.3142 | F17: 315.0718 | G17: 2349.1399 | H17: 4647.6658 | I17: 2529.3725 | J17: 350.69455 | K17: 60.121738 | L17: 1133.3671 | M17: 1800.0868 | N17: 305.1994 | P17: 20697.644 | R17: 30901.887 | T17: 0 | V17: 715.5493 | X17: 6164.3482 | Z17: -2.5610537 | AB17: 3003.0163 | AD17: 61479.884
B18: 7 | C18: 1062.4134 | D18: 1833.5671 | E18: 4744.7545 | F18: 530.47941 | G18: 1031.9694 | H18: 7309.357 | I18: 8000.1397 | J18: 904.07699 | K18: 77.339441 | L18: 1471.0035 | M18: 863.6284 | N18: 594.23803 | P18: 28422.967 | R18: 11716.771 | T18: 0 | V18: 10.022819 | X18: 2908.8035 | Z18: 0 | AB18: 4108.0306 | AD18: 47166.595
B19: 8 | C19: 310.09646 | D19: 274.66529 | E19: 810.19139 | F19: 363.09324 | G19: 584.48261 | H19: 1750.6707 | I19: 635.75459 | J19: 5982.5788 | K19: 617.14535 | L19: 898.43815 | M19: 327.8381 | N19: 248.25607 | P19: 12803.211 | R19: 7988.7193 | T19: 0 | V19: 228.71296 | X19: 61.206593 | Z19: 0 | AB19: 723.43575 | AD19: 21805.285
B20: 9 | C20: 52.019253 | D20: 56.805471 | E20: 456.05278 | F20: 48.722292 | G20: 112.4127 | H20: 2527.883 | I20: 644.81758 | J20: 458.1623 | K20: 332.54365 | L20: 654.14719 | M20: 893.16879 | N20: 167.63693 | P20: 6404.372 | R20: 19091.525 | T20: 0 | V20: 0.13745594 | X20: 121.53446 | Z20: 0 | AB20: 49.574675 | AD20: 25667.144
B21: 10 | C21: 749.34541 | D21: 4370.2377 | E21: 3411.4399 | F21: 1061.4774 | G21: 1714.9704 | H21: 5489.8329 | I21: 2646.5876 | J21: 2399.6729 | K21: 453.41049 | L21: 4585.6626 | M21: 2007.4008 | N21: 950.45331 | P21: 29840.491 | R21: 1570.0364 | T21: 0 | V21: 73.289574 | X21: 4072.6307 | Z21: 0.00051274778 | AB21: 1232.2601 | AD21: 36788.709
B22: 11 | C22: 26.14601 | D22: 71.001523 | E22: 104.66134 | F22: 18.745371 | G22: 86.166105 | H22: 172.29881 | I22: 243.82967 | J22: 75.432658 | K22: 10.201214 | L22: 92.444838 | M22: 2107.4689 | N22: 59.650812 | P22: 3068.0473 | R22: 18747.743 | T22: 1392.238 | V22: 21792.013 | X22: 642.23939 | Z22: -0.00822044 | AB22: 47.160185 | AD22: 45689.433
B23: 12 | C23: 45.019161 | D23: 105.95826 | E23: 162.04711 | F23: 22.240215 | G23: 24.677827 | H23: 126.68165 | I23: 161.78894 | J23: 15.357297 | K23: 5.3999492 | L23: 24.258369 | M23: 36.656949 | N23: 59.206028 | P23: 789.29176 | R23: 298.66272 | T23: 3.5741954e-32 | V23: 15301.742 | X23: 57.798045 | Z23: -0.5630563 | AB23: 48.890801 | AD23: 16495.822
B25: Total | C25: 12240.16 | D25: 20644.118 | E25: 44560.721 | F25: 5106.9242 | G25: 18271.209 | H25: 28240.437 | I25: 18271.001 | J25: 10538.901 | K25: 4758.17 | L25: 9887.7589 | M25: 10775.364 | N25: 3404.7749 | P25: 186699.54 | R25: 119193.54 | T25: 1392.238 | V25: 38293.979 | X25: 48379.142 | Z25: -751.86178 | AB25: 90621.762 | AD25: 483828.33
B28: Importaciones precios cif | C28: 2621.9281 | D28: 3729.7252 | E28: 22990.792 | F28: 4723.5612 | G28: 3217.1656 | H28: 4586.7671 | I28: 8548.9235 | J28: 2005.0089 | K28: 63.643435 | L28: 1472.4797 | M28: 1702.1442 | N28: 864.20392 | P28: 56526.343
B29: Impuestos sobre productos | C29: -6.1578672 | D29: -25.855656 | E29: 33.943738 | F29: -4.7832725 | G29: 203.44534 | H29: 116.2025 | I29: 917.55741 | J29: 580.02992 | K29: 94.178253 | L29: 339.14555 | M29: 1463.9757 | N29: 581.57113 | P29: 4293.2527
B30: Derechos de importación | C30: 29.741379 | D30: 17.183697 | E30: 181.62211 | F30: 27.483605 | G30: 25.987829 | H30: 50.736195 | I30: 99.295578 | J30: 2.6035014 | K30: 0.85384691 | L30: 16.745443 | M30: 37.971329 | N30: 7.598456 | P30: 497.82297
B32: Valor agregado | C32: 8509.3233 | D32: 35174.718 | E32: 24926.686 | F32: 6107.7565 | G32: 15428.063 | H32: 28485.742 | I32: 19329.818 | J32: 8678.7424 | K32: 20750.298 | L32: 25072.579 | M32: 31709.977 | N32: 11637.674 | P32: 235811.38
B34: Remuneraciones de asalariados | C34: 2645.6813 | D34: 3769.3374 | E34: 8599.0723 | F34: 1424.9129 | G34: 8252.3108 | H34: 17055.342 | I34: 8964.348 | J34: 6293.9209 | K34: 727.11375 | L34: 11502.884 | M34: 24353.808 | N34: 9302.2421 | P34: 102890.97
B35: Excedente bruto de explotación | C35: 5751.1043 | D35: 31179.317 | E35: 15959.068 | F35: 4355.3375 | G35: 6990.6379 | H35: 10834.619 | I35: 11032.477 | J35: 1921.8605 | K35: 18450.284 | L35: 13396.454 | M35: 7029.9534 | N35: 2305.962 | P35: 129207.07
B36: Impuestos netos sobre la producción | C36: 112.53764 | D36: 226.06359 | E36: 368.54504 | F36: 327.50616 | G36: 185.11459 | H36: 595.78124 | I36: -667.00712 | J36: 462.96098 | K36: 1572.9009 | L36: 173.24186 | M36: 326.21624 | N36: 29.469967 | P36: 3713.3311
B38: Producción precios básicos | C38: 23394.995 | D38: 59539.889 | E38: 92693.764 | F38: 15960.942 | G38: 37145.871 | H38: 61479.884 | I38: 47166.595 | J38: 21805.285 | K38: 25667.144 | L38: 36788.709 | M38: 45689.433 | N38: 16495.822 | O38: 0 | P38: 483828.33

Sheet Preparado
E2: Demanda intermedia | F2: Demanda intermedia | G2: Demanda intermedia | H2: Demanda intermedia | I2: Demanda intermedia | J2: Demanda intermedia | K2: Demanda intermedia | L2: Demanda intermedia | M2: Demanda intermedia | N2: Demanda intermedia | O2: Demanda intermedia | P2: Demanda intermedia | Q2: Consumo de hogares | R2: Consumo de IPSFL | S2: Consumo de gobierno | T2: Formación bruta de capital fijo | U2: Variación de existencias | V2: Exportaciones
E3: 1 | F3: 2 | G3: 3 | H3: 4 | I3: 5 | J3: 6 | K3: 7 | L3: 8 | M3: 9 | N3: 10 | O3: 11 | P3: 12 | Q3: Ninguno | R3: Ninguno | S3: Ninguno | T3: Ninguno | U3: Ninguno | V3: Ninguno
E4: Agropecuario-silvícola y Pesca | F4: Minería | G4: Industria manufacturera | H4: Electricidad, gas, agua y gestión de desechos | I4: Construcción | J4: Comercio, hoteles y restaurantes | K4: Transporte, comunicaciones y servicios de información | L4: Intermediación financiera | M4: Servicios inmobiliarios y de vivienda | N4: Servicios empresariales | O4: Servicios personales | P4: Administración pública | Q4: Ninguno | R4: Ninguno | S4: Ninguno | T4: Ninguno | U4: Ninguno | V4: Ninguno
E5: =CONCATENATE(E2, "_",E3,"_",E4) -> Demanda intermedia_1_Agropecuario-silvícola y Pesca | F5: =CONCATENATE(F2, "_",F3,"_",F4) -> Demanda intermedia_2_Minería | G5: =CONCATENATE(G2, "_",G3,"_",G4) -> Demanda intermedia_3_Industria manufacturera | H5: =CONCATENATE(H2, "_",H3,"_",H4) -> Demanda intermedia_4_Electricidad, gas, agua y gestión de desechos | I5: =CONCATENATE(I2, "_",I3,"_",I4) -> Demanda intermedia_5_Construcción | J5: =CONCATENATE(J2, "_",J3,"_",J4) -> Demanda intermedia_6_Comercio, hoteles y restaurantes | K5: =CONCATENATE(K2, "_",K3,"_",K4) -> Demanda intermedia_7_Transporte, comunicaciones y servicios de información | L5: =CONCATENATE(L2, "_",L3,"_",L4) -> Demanda intermedia_8_Intermediación financiera | ... V5: =CONCATENATE(V2, "_",V3,"_",V4) -> Exportaciones_Ninguno_Ninguno
A6: Oferta intermedia | B6: 1 | C6: Agropecuario-silvícola y Pesca | D6: =CONCATENATE(A6,"_", B6,"_",C6) -> Oferta intermedia_1_Agropecuario-silvícola y Pesca | E6: 4115.2532 | F6: 0.64223707 | G6: 11866.039 | H6: 41.40853 | I6: 13.540523 | J6: 323.50973 | K6: 3.71898 | L6: 1.17387 | M6: 0.046620561 | N6: 6.0921412 | O6: 59.351153 | P6: 62.713022 | Q6: 2783.6759 | R6: 0 | S6: 0.02668751 | T6: 790.68687 | U6: -133.35792 | V6: 3460.4746
A7: Oferta intermedia | B7: 2 | C7: Minería | D7: =CONCATENATE(A7,"_", B7,"_",C7) -> Oferta intermedia_2_Minería | E7: 17.284375 | F7: 5176.8488 | G7: 3249.0835 | H7: 69.390609 | I7: 194.00931 | J7: 47.012199 | K7: 26.834354 | L7: 26.634541 | M7: 5.9874064 | N7: 48.327516 | O7: 28.725165 | P7: 9.6188119 | Q7: 46.319553 | R7: 0 | S7: 2.7228123 | T7: 704.96651 | U7: -315.19166 | V7: 50201.315
A8: Oferta intermedia | B8: 3 | C8: Industria manufacturera | D8: =CONCATENATE(A8,"_", B8,"_",C8) -> Oferta intermedia_3_Industria manufacturera | E8: 4649.3296 | F8: 3599.6667 | G8: 12335.839 | H8: 629.30829 | I8: 6599.0789 | J8: 4798.4364 | K8: 2849.6015 | L8: 175.11488 | M8: 62.121384 | N8: 724.34216 | O8: 2143.2518 | P8: 363.03963 | Q8: 22272.496 | R8: 0 | S8: 86.443491 | T8: 4045.8566 | U8: -300.63449 | V8: 27660.472
A9: Oferta intermedia | B9: 4 | C9: Electricidad, gas, agua y gestión de desechos | D9: =CONCATENATE(A9,"_", B9,"_",C9) -> Oferta intermedia_4_Electricidad, gas, agua y gestión de desechos | E9: 245.39146 | F9: 3380.9071 | G9: 2940.4899 | H9: 2005.3179 | I9: 268.21389 | J9: 987.68204 | K9: 498.25205 | L9: 134.92253 | M9: 217.21723 | N9: 231.67899 | O9: 487.05718 | P9: 578.82228 | Q9: 3763.8962 | R9: 0 | S9: 83.189665 | T9: 55.968354 | U9: 0.45411781 | V9: 81.48139
A10: Oferta intermedia | B10: 5 | C10: Construcción | D10: =CONCATENATE(A10,"_", B10,"_",C10) -> Oferta intermedia_5_Construcción | E10: 1.0332716 | F10: 3.0356266 | G10: 10.808026 | H10: 1.6691959 | I10: 5292.5471 | J10: 59.406448 | K10: 30.303137 | L10: 15.079325 | M10: 2916.6355 | N10: 17.996333 | O10: 20.730085 | P10: 5.9405624 | Q10: 11.802968 | R10: 0 | S10: 0.12944474 | T10: 28753.103 | U10: 0 | V10: 5.6507348
A11: Oferta intermedia | B11: 6 | C11: Comercio, hoteles y restaurantes | D11: =CONCATENATE(A11,"_", B11,"_",C11) -> Oferta intermedia_6_Comercio, hoteles y restaurantes | E11: 966.82834 | F11: 1770.7817 | G11: 4469.3142 | H11: 315.0718 | I11: 2349.1399 | J11: 4647.6658 | K11: 2529.3725 | L11: 350.69455 | M11: 60.121738 | N11: 1133.3671 | O11: 1800.0868 | P11: 305.1994 | Q11: 30901.887 | R11: 0 | S11: 715.5493 | T11: 6164.3482 | U11: -2.5610537 | V11: 3003.0163
A12: Oferta intermedia | B12: 7 | C12: Transporte, comunicaciones y servicios de información | D12: =CONCATENATE(A12,"_", B12,"_",C12) -> Oferta intermedia_7_Transporte, comunicaciones y servicios de información | E12: 1062.4134 | F12: 1833.5671 | G12: 4744.7545 | H12: 530.47941 | I12: 1031.9694 | J12: 7309.357 | K12: 8000.1397 | L12: 904.07699 | M12: 77.339441 | N12: 1471.0035 | O12: 863.6284 | P12: 594.23803 | Q12: 11716.771 | R12: 0 | S12: 10.022819 | T12: 2908.8035 | U12: 0 | V12: 4108.0306
A13: Oferta intermedia | B13: 8 | C13: Intermediación financiera | D13: =CONCATENATE(A13,"_", B13,"_",C13) -> Oferta intermedia_8_Intermediación financiera | E13: 310.09646 | F13: 274.66529 | G13: 810.19139 | H13: 363.09324 | I13: 584.48261 | J13: 1750.6707 | K13: 635.75459 | L13: 5982.5788 | M13: 617.14535 | N13: 898.43815 | O13: 327.8381 | P13: 248.25607 | Q13: 7988.7193 | R13: 0 | S13: 228.71296 | T13: 61.206593 | U13: 0 | V13: 723.43575
A14: Oferta intermedia | B14: 9 | C14: Servicios inmobiliarios y de vivienda | D14: =CONCATENATE(A14,"_", B14,"_",C14) -> Oferta intermedia_9_Servicios inmobiliarios y de vivienda | E14: 52.019253 | F14: 56.805471 | G14: 456.05278 | H14: 48.722292 | I14: 112.4127 | J14: 2527.883 | K14: 644.81758 | L14: 458.1623 | M14: 332.54365 | N14: 654.14719 | O14: 893.16879 | P14: 167.63693 | Q14: 19091.525 | R14: 0 | S14: 0.13745594 | T14: 121.53446 | U14: 0 | V14: 49.574675
A15: Oferta intermedia | B15: 10 | C15: Servicios empresariales | D15: =CONCATENATE(A15,"_", B15,"_",C15) -> Oferta intermedia_10_Servicios empresariales | E15: 749.34541 | F15: 4370.2377 | G15: 3411.4399 | H15: 1061.4774 | I15: 1714.9704 | J15: 5489.8329 | K15: 2646.5876 | L15: 2399.6729 | M15: 453.41049 | N15: 4585.6626 | O15: 2007.4008 | P15: 950.45331 | Q15: 1570.0364 | R15: 0 | S15: 73.289574 | T15: 4072.6307 | U15: 0.00051274778 | V15: 1232.2601
A16: Oferta intermedia | B16: 11 | C16: Servicios personales | D16: =CONCATENATE(A16,"_", B16,"_",C16) -> Oferta intermedia_11_Servicios personales | E16: 26.14601 | F16: 71.001523 | G16: 104.66134 | H16: 18.745371 | I16: 86.166105 | J16: 172.29881 | K16: 243.82967 | L16: 75.432658 | M16: 10.201214 | N16: 92.444838 | O16: 2107.4689 | P16: 59.650812 | Q16: 18747.743 | R16: 1392.238 | S16: 21792.013 | T16: 642.23939 | U16: -0.00822044 | V16: 47.160185
A17: Oferta intermedia | B17: 12 | C17: Administración pública | D17: =CONCATENATE(A17,"_", B17,"_",C17) -> Oferta intermedia_12_Administración pública | E17: 45.019161 | F17: 105.95826 | G17: 162.04711 | H17: 22.240215 | I17: 24.677827 | J17: 126.68165 | K17: 161.78894 | L17: 15.357297 | M17: 5.3999492 | N17: 24.258369 | O17: 36.656949 | P17: 59.206028 | Q17: 298.66272 | R17: 3.5741954e-32 | S17: 15301.742 | T17: 57.798045 | U17: -0.5630563 | V17: 48.890801

Sheet Resultado
A1: Detalles de Suma de Valor
A3: Fila | B3: Columna | C3: Valor | D3: Transaccion Fila | E3: Código Sector Fila | F3: Sector Fila | G3: Bioeconomía filas | H3: Transacción Columnas | I3: Código Sector Columna | J3: Sector Columna | K3: Bioeconomía columnas
A4: Oferta intermedia_1_Agropecuario-silvícola y Pesca | B4: Demanda intermedia_1_Agropecuario-silvícola y Pesca | C4: 4115.2532 | D4: Oferta intermedia | E4: 1 | F4: Agropecuario-silvícola y Pesca | G4: =VLOOKUP(E4,Bioeconomía!$A$1:$C$13,3,FALSE) -> Bioeconomía | H4: Demanda intermedia | I4: 1 | J4: Agropecuario-silvícola y Pesca | K4: =VLOOKUP(I4,Bioeconomía!$A$1:$C$13,3,FALSE) -> Bioeconomía
A5: Oferta intermedia_1_Agropecuario-silvícola y Pesca | B5: Demanda intermedia_2_Minería | C5: 0.64223707 | D5: Oferta intermedia | E5: 1 | F5: Agropecuario-silvícola y Pesca | G5: =VLOOKUP(E5,Bioeconomía!$A$1:$C$13,3,FALSE) -> Bioeconomía | H5: Demanda intermedia | I5: 2 | J5: Minería | K5: =VLOOKUP(I5,Bioeconomía!$A$1:$C$13,3,FALSE) -> No Bioeconomía
A6: Oferta intermedia_1_Agropecuario-silvícola y Pesca | B6: Demanda intermedia_3_Industria manufacturera | C6: 11866.039 | D6: Oferta intermedia | E6: 1 | F6: Agropecuario-silvícola y Pesca | G6: =VLOOKUP(E6,Bioeconomía!$A$1:$C$13,3,FALSE) -> Bioeconomía | H6: Demanda intermedia | I6: 3 | J6: Industria manufacturera | K6: =VLOOKUP(I6,Bioeconomía!$A$1:$C$13,3,FALSE) -> No Bioeconomía
A7: Oferta intermedia_1_Agropecuario-silvícola y Pesca | B7: Demanda intermedia_4_Electricidad, gas, agua y gestión de desechos | C7: 41.40853 | D7: Oferta intermedia | E7: 1 | F7: Agropecuario-silvícola y Pesca | G7: =VLOOKUP(E7,Bioeconomía!$A$1:$C$13,3,FALSE) -> Bioeconomía | H7: Demanda intermedia | I7: 4 | J7: Electricidad, gas, agua y gestión de desechos | K7: =VLOOKUP(I7,Bioeconomía!$A$1:$C$13,3,FALSE) -> No Bioeconomía
A8: Oferta intermedia_1_Agropecuario-silvícola y Pesca | B8: Demanda intermedia_5_Construcción | C8: 13.540523 | D8: Oferta intermedia | E8: 1 | F8: Agropecuario-silvícola y Pesca | G8: =VLOOKUP(E8,Bioeconomía!$A$1:$C$13,3,FALSE) -> Bioeconomía | H8: Demanda intermedia | I8: 5 | J8: Construcción | K8: =VLOOKUP(I8,Bioeconomía!$A$1:$C$13,3,FALSE) -> No Bioeconomía
A9: Oferta intermedia_1_Agropecuario-silvícola y Pesca | B9: Demanda intermedia_6_Comercio, hoteles y restaurantes | C9: 323.50973 | D9: Oferta intermedia | E9: 1 | F9: Agropecuario-silvícola y Pesca | G9: =VLOOKUP(E9,Bioeconomía!$A$1:$C$13,3,FALSE) -> Bioeconomía | H9: Demanda intermedia | I9: 6 | J9: Comercio, hoteles y restaurantes | K9: =VLOOKUP(I9,Bioeconomía!$A$1:$C$13,3,FALSE) -> No Bioeconomía
A10: Oferta intermedia_1_Agropecuario-silvícola y Pesca | B10: Demanda intermedia_7_Transporte, comunicaciones y servicios de información | C10: 3.71898 | D10: Oferta intermedia | E10: 1 | F10: Agropecuario-silvícola y Pesca | G10: =VLOOKUP(E10,Bioeconomía!$A$1:$C$13,3,FALSE) -> Bioeconomía | H10: Demanda intermedia | I10: 7 | J10: Transporte, comunicaciones y servicios de información | K10: =VLOOKUP(I10,Bioeconomía!$A$1:$C$13,3,FALSE) -> No Bioeconomía
A11: Oferta intermedia_1_Agropecuario-silvícola y Pesca | B11: Demanda intermedia_8_Intermediación financiera | C11: 1.17387 | D11: Oferta intermedia | E11: 1 | F11: Agropecuario-silvícola y Pesca | G11: =VLOOKUP(E11,Bioeconomía!$A$1:$C$13,3,FALSE) -> Bioeconomía | H11: Demanda intermedia | I11: 8 | J11: Intermediación financiera | K11: =VLOOKUP(I11,Bioeconomía!$A$1:$C$13,3,FALSE) -> No Bioeconomía
A12: Oferta intermedia_1_Agropecuario-silvícola y Pesca | B12: Demanda intermedia_9_Servicios inmobiliarios y de vivienda | C12: 0.046620561 | D12: Oferta intermedia | E12: 1 | F12: Agropecuario-silvícola y Pesca | G12: =VLOOKUP(E12,Bioeconomía!$A$1:$C$13,3,FALSE) -> Bioeconomía | H12: Demanda intermedia | I12: 9 | J12: Servicios inmobiliarios y de vivienda | K12: =VLOOKUP(I12,Bioeconomía!$A$1:$C$13,3,FALSE) -> No Bioeconomía
A13: Oferta intermedia_1_Agropecuario-silvícola y Pesca | B13: Demanda intermedia_10_Servicios empresariales | C13: 6.0921412 | D13: Oferta intermedia | E13: 1 | F13: Agropecuario-silvícola y Pesca | G13: =VLOOKUP(E13,Bioeconomía!$A$1:$C$13,3,FALSE) -> Bioeconomía | H13: Demanda intermedia | I13: 10 | J13: Servicios empresariales | K13: =VLOOKUP(I13,Bioeconomía!$A$1:$C$13,3,FALSE) -> Bioeconomía extendida
A14: Oferta intermedia_1_Agropecuario-silvícola y Pesca | B14: Demanda intermedia_11_Servicios personales | C14: 59.351153 | D14: Oferta intermedia | E14: 1 | F14: Agropecuario-silvícola y Pesca | G14: =VLOOKUP(E14,Bioeconomía!$A$1:$C$13,3,FALSE) -> Bioeconomía | H14: Demanda intermedia | I14: 11 | J14: Servicios personales | K14: =VLOOKUP(I14,Bioeconomía!$A$1:$C$13,3,FALSE) -> No Bioeconomía
A15: Oferta intermedia_1_Agropecuario-silvícola y Pesca | B15: Demanda intermedia_12_Administración pública | C15: 62.713022 | D15: Oferta intermedia | E15: 1 | F15: Agropecuario-silvícola y Pesca | G15: =VLOOKUP(E15,Bioeconomía!$A$1:$C$13,3,FALSE) -> Bioeconomía | H15: Demanda intermedia | I15: 12 | J15: Administración pública | K15: =VLOOKUP(I15,Bioeconomía!$A$1:$C$13,3,FALSE) -> No Bioeconomía
A16: Oferta intermedia_1_Agropecuario-silvícola y Pesca | B16: Consumo de hogares_Ninguno_Ninguno | C16: 2783.6759 | D16: Oferta intermedia | E16: 1 | F16: Agropecuario-silvícola y Pesca | G16: =VLOOKUP(E16,Bioeconomía!$A$1:$C$13,3,FALSE) -> Bioeconomía | H16: Consumo de hogares | I16: Ninguno | J16: Ninguno | K16: =VLOOKUP(I16,Bioeconomía!$A$1:$C$13,3,FALSE) -> Ninguno
A17: Oferta intermedia_1_Agropecuario-silvícola y Pesca | B17: Consumo de IPSFL_Ninguno_Ninguno | C17: 0 | D17: Oferta intermedia | E17: 1 | F17: Agropecuario-silvícola y Pesca | G17: =VLOOKUP(E17,Bioeconomía!$A$1:$C$13,3,FALSE) -> Bioeconomía | H17: Consumo de IPSFL | I17: Ninguno | J17: Ninguno | K17: =VLOOKUP(I17,Bioeconomía!$A$1:$C$13,3,FALSE) -> Ninguno
A18: Oferta intermedia_1_Agropecuario-silvícola y Pesca | B18: Consumo de gobierno_Ninguno_Ninguno | C18: 0.02668751 | D18: Oferta intermedia | E18: 1 | F18: Agropecuario-silvícola y Pesca | G18: =VLOOKUP(E18,Bioeconomía!$A$1:$C$13,3,FALSE) -> Bioeconomía | H18: Consumo de gobierno | I18: Ninguno | J18: Ninguno | K18: =VLOOKUP(I18,Bioeconomía!$A$1:$C$13,3,FALSE) -> Ninguno
A19: Oferta intermedia_1_Agropecuario-silvícola y Pesca | B19: Formación bruta de capital fijo_Ninguno_Ninguno | C19: 790.68687 | D19: Oferta intermedia | E19: 1 | F19: Agropecuario-silvícola y Pesca | G19: =VLOOKUP(E19,Bioeconomía!$A$1:$C$13,3,FALSE) -> Bioeconomía | H19: Formación bruta de capital fijo | I19: Ninguno | J19: Ninguno | K19: =VLOOKUP(I19,Bioeconomía!$A$1:$C$13,3,FALSE) -> Ninguno
A20: Oferta intermedia_1_Agropecuario-silvícola y Pesca | B20: Variación de existencias_Ninguno_Ninguno | C20: -133.35792 | D20: Oferta intermedia | E20: 1 | F20: Agropecuario-silvícola y Pesca | G20: =VLOOKUP(E20,Bioeconomía!$A$1:$C$13,3,FALSE) -> Bioeconomía | H20: Variación de existencias | I20: Ninguno | J20: Ninguno | K20: =VLOOKUP(I20,Bioeconomía!$A$1:$C$13,3,FALSE) -> Ninguno
A21: Oferta intermedia_1_Agropecuario-silvícola y Pesca | B21: Exportaciones_Ninguno_Ninguno | C21: 3460.4746 | D21: Oferta intermedia | E21: 1 | F21: Agropecuario-silvícola y Pesca | G21: =VLOOKUP(E21,Bioeconomía!$A$1:$C$13,3,FALSE) -> Bioeconomía | H21: Exportaciones | I21: Ninguno | J21: Ninguno | K21: =VLOOKUP(I21,Bioeconomía!$A$1:$C$13,3,FALSE) -> Ninguno
A22: Oferta intermedia_2_Minería | B22: Demanda intermedia_1_Agropecuario-silvícola y Pesca | C22: 17.284375 | D22: Oferta intermedia | E22: 2 | F22: Minería | G22: =VLOOKUP(E22,Bioeconomía!$A$1:$C$13,3,FALSE) -> No Bioeconomía | H22: Demanda intermedia | I22: 1 | J22: Agropecuario-silvícola y Pesca | K22: =VLOOKUP(I22,Bioeconomía!$A$1:$C$13,3,FALSE) -> Bioeconomía
A23: Oferta intermedia_2_Minería | B23: Demanda intermedia_2_Minería | C23: 5176.8488 | D23: Oferta intermedia | E23: 2 | F23: Minería | G23: =VLOOKUP(E23,Bioeconomía!$A$1:$C$13,3,FALSE) -> No Bioeconomía | H23: Demanda intermedia | I23: 2 | J23: Minería | K23: =VLOOKUP(I23,Bioeconomía!$A$1:$C$13,3,FALSE) -> No Bioeconomía
A24: Oferta intermedia_2_Minería | B24: Demanda intermedia_3_Industria manufacturera | C24: 3249.0835 | D24: Oferta intermedia | E24: 2 | F24: Minería | G24: =VLOOKUP(E24,Bioeconomía!$A$1:$C$13,3,FALSE) -> No Bioeconomía | H24: Demanda intermedia | I24: 3 | J24: Industria manufacturera | K24: =VLOOKUP(I24,Bioeconomía!$A$1:$C$13,3,FALSE) -> No Bioeconomía
A25: Oferta intermedia_2_Minería | B25: Demanda intermedia_4_Electricidad, gas, agua y gestión de desechos | C25: 69.390609 | D25: Oferta intermedia | E25: 2 | F25: Minería | G25: =VLOOKUP(E25,Bioeconomía!$A$1:$C$13,3,FALSE) -> No Bioeconomía | H25: Demanda intermedia | I25: 4 | J25: Electricidad, gas, agua y gestión de desechos | K25: =VLOOKUP(I25,Bioeconomía!$A$1:$C$13,3,FALSE) -> No Bioeconomía
A26: Oferta intermedia_2_Minería | B26: Demanda intermedia_5_Construcción | C26: 194.00931 | D26: Oferta intermedia | E26: 2 | F26: Minería | G26: =VLOOKUP(E26,Bioeconomía!$A$1:$C$13,3,FALSE) -> No Bioeconomía | H26: Demanda intermedia | I26: 5 | J26: Construcción | K26: =VLOOKUP(I26,Bioeconomía!$A$1:$C$13,3,FALSE) -> No Bioeconomía
A27: Oferta intermedia_2_Minería | B27: Demanda intermedia_6_Comercio, hoteles y restaurantes | C27: 47.012199 | D27: Oferta intermedia | E27: 2 | F27: Minería | G27: =VLOOKUP(E27,Bioeconomía!$A$1:$C$13,3,FALSE) -> No Bioeconomía | H27: Demanda intermedia | I27: 6 | J27: Comercio, hoteles y restaurantes | K27: =VLOOKUP(I27,Bioeconomía!$A$1:$C$13,3,FALSE) -> No Bioeconomía
A28: Oferta intermedia_2_Minería | B28: Demanda intermedia_7_Transporte, comunicaciones y servicios de información | C28: 26.834354 | D28: Oferta intermedia | E28: 2 | F28: Minería | G28: =VLOOKUP(E28,Bioeconomía!$A$1:$C$13,3,FALSE) -> No Bioeconomía | H28: Demanda intermedia | I28: 7 | J28: Transporte, comunicaciones y servicios de información | K28: =VLOOKUP(I28,Bioeconomía!$A$1:$C$13,3,FALSE) -> No Bioeconomía
A29: Oferta intermedia_2_Minería | B29: Demanda intermedia_8_Intermediación financiera | C29: 26.634541 | D29: Oferta intermedia | E29: 2 | F29: Minería | G29: =VLOOKUP(E29,Bioeconomía!$A$1:$C$13,3,FALSE) -> No Bioeconomía | H29: Demanda intermedia | I29: 8 | J29: Intermediación financiera | K29: =VLOOKUP(I29,Bioeconomía!$A$1:$C$13,3,FALSE) -> No Bioeconomía
A30: Oferta intermedia_2_Minería | B30: Demanda intermedia_9_Servicios inmobiliarios y de vivienda | C30: 5.9874064 | D30: Oferta intermedia | E30: 2 | F30: Minería | G30: =VLOOKUP(E30,Bioeconomía!$A$1:$C$13,3,FALSE) -> No Bioeconomía | H30: Demanda intermedia | I30: 9 | J30: Servicios inmobiliarios y de vivienda | K30: =VLOOKUP(I30,Bioeconomía!$A$1:$C$13,3,FALSE) -> No Bioeconomía
A31: Oferta intermedia_2_Minería | B31: Demanda intermedia_10_Servicios empresariales | C31: 48.327516 | D31: Oferta intermedia | E31: 2 | F31: Minería | G31: =VLOOKUP(E31,Bioeconomía!$A$1:$C$13,3,FALSE) -> No Bioeconomía | H31: Demanda intermedia | I31: 10 | J31: Servicios empresariales | K31: =VLOOKUP(I31,Bioeconomía!$A$1:$C$13,3,FALSE) -> Bioeconomía extendida
A32: Oferta intermedia_2_Minería | B32: Demanda intermedia_11_Servicios personales | C32: 28.725165 | D32: Oferta intermedia | E32: 2 | F32: Minería | G32: =VLOOKUP(E32,Bioeconomía!$A$1:$C$13,3,FALSE) -> No Bioeconomía | H32: Demanda intermedia | I32: 11 | J32: Servicios personales | K32: =VLOOKUP(I32,Bioeconomía!$A$1:$C$13,3,FALSE) -> No Bioeconomía
A33: Oferta intermedia_2_Minería | B33: Demanda intermedia_12_Administración pública | C33: 9.6188119 | D33: Oferta intermedia | E33: 2 | F33: Minería | G33: =VLOOKUP(E33,Bioeconomía!$A$1:$C$13,3,FALSE) -> No Bioeconomía | H33: Demanda intermedia | I33: 12 | J33: Administración pública | K33: =VLOOKUP(I33,Bioeconomía!$A$1:$C$13,3,FALSE) -> No Bioeconomía
A34: Oferta intermedia_2_Minería | B34: Consumo de hogares_Ninguno_Ninguno | C34: 46.319553 | D34: Oferta intermedia | E34: 2 | F34: Minería | G34: =VLOOKUP(E34,Bioeconomía!$A$1:$C$13,3,FALSE) -> No Bioeconomía | H34: Consumo de hogares | I34: Ninguno | J34: Ninguno | K34: =VLOOKUP(I34,Bioeconomía!$A$1:$C$13,3,FALSE) -> Ninguno
A35: Oferta intermedia_2_Minería | B35: Consumo de IPSFL_Ninguno_Ninguno | C35: 0 | D35: Oferta intermedia | E35: 2 | F35: Minería | G35: =VLOOKUP(E35,Bioeconomía!$A$1:$C$13,3,FALSE) -> No Bioeconomía | H35: Consumo de IPSFL | I35: Ninguno | J35: Ninguno | K35: =VLOOKUP(I35,Bioeconomía!$A$1:$C$13,3,FALSE) -> Ninguno
A36: Oferta intermedia_2_Minería | B36: Consumo de gobierno_Ninguno_Ninguno | C36: 2.7228123 | D36: Oferta intermedia | E36: 2 | F36: Minería | G36: =VLOOKUP(E36,Bioeconomía!$A$1:$C$13,3,FALSE) -> No Bioeconomía | H36: Consumo de gobierno | I36: Ninguno | J36: Ninguno | K36: =VLOOKUP(I36,Bioeconomía!$A$1:$C$13,3,FALSE) -> Ninguno
A37: Oferta intermedia_2_Minería | B37: Formación bruta de capital fijo_Ninguno_Ninguno | C37: 704.96651 | D37: Oferta intermedia | E37: 2 | F37: Minería | G37: =VLOOKUP(E37,Bioeconomía!$A$1:$C$13,3,FALSE) -> No Bioeconomía | H37: Formación bruta de capital fijo | I37: Ninguno | J37: Ninguno | K37: =VLOOKUP(I37,Bioeconomía!$A$1:$C$13,3,FALSE) -> Ninguno
A38: Oferta intermedia_2_Minería | B38: Variación de existencias_Ninguno_Ninguno | C38: -315.19166 | D38: Oferta intermedia | E38: 2 | F38: Minería | G38: =VLOOKUP(E38,Bioeconomía!$A$1:$C$13,3,FALSE) -> No Bioeconomía | H38: Variación de existencias | I38: Ninguno | J38: Ninguno | K38: =VLOOKUP(I38,Bioeconomía!$A$1:$C$13,3,FALSE) -> Ninguno
A39: Oferta intermedia_2_Minería | B39: Exportaciones_Ninguno_Ninguno | C39: 50201.315 | D39: Oferta intermedia | E39: 2 | F39: Minería | G39: =VLOOKUP(E39,Bioeconomía!$A$1:$C$13,3,FALSE) -> No Bioeconomía | H39: Exportaciones | I39: Ninguno | J39: Ninguno | K39: =VLOOKUP(I39,Bioeconomía!$A$1:$C$13,3,FALSE) -> Ninguno
A40: Oferta intermedia_3_Industria manufacturera | B40: Demanda intermedia_1_Agropecuario-silvícola y Pesca | C40: 4649.3296 | D40: Oferta intermedia | E40: 3 | F40: Industria manufacturera | G40: =VLOOKUP(E40,Bioeconomía!$A$1:$C$13,3,FALSE) -> No Bioeconomía | H40: Demanda intermedia | I40: 1 | J40: Agropecuario-silvícola y Pesca | K40: =VLOOKUP(I40,Bioeconomía!$A$1:$C$13,3,FALSE) -> Bioeconomía
A41: Oferta intermedia_3_Industria manufacturera | B41: Demanda intermedia_2_Minería | C41: 3599.6667 | D41: Oferta intermedia | E41: 3 | F41: Industria manufacturera | G41: =VLOOKUP(E41,Bioeconomía!$A$1:$C$13,3,FALSE) -> No Bioeconomía | H41: Demanda intermedia | I41: 2 | J41: Minería | K41: =VLOOKUP(I41,Bioeconomía!$A$1:$C$13,3,FALSE) -> No Bioeconomía
...

Sheet Pruebe usted

Sheet Filas
A1: Transaccion Fila | B1: Código Sector Fila | C1: Sector Fila
A2: Oferta intermedia | B2: 1 | C2: Agropecuario-silvícola y Pesca
A3: Oferta intermedia | B3: 1 | C3: Agropecuario-silvícola y Pesca
A4: Oferta intermedia | B4: 1 | C4: Agropecuario-silvícola y Pesca
A5: Oferta intermedia | B5: 1 | C5: Agropecuario-silvícola y Pesca
A6: Oferta intermedia | B6: 1 | C6: Agropecuario-silvícola y Pesca
A7: Oferta intermedia | B7: 1 | C7: Agropecuario-silvícola y Pesca
A8: Oferta intermedia | B8: 1 | C8: Agropecuario-silvícola y Pesca
A9: Oferta intermedia | B9: 1 | C9: Agropecuario-silvícola y Pesca
A10: Oferta intermedia | B10: 1 | C10: Agropecuario-silvícola y Pesca
A11: Oferta intermedia | B11: 1 | C11: Agropecuario-silvícola y Pesca
A12: Oferta intermedia | B12: 1 | C12: Agropecuario-silvícola y Pesca
A13: Oferta intermedia | B13: 1 | C13: Agropecuario-silvícola y Pesca
... A217: Oferta intermedia | B217: 12 | C217: Administración pública

Sheet Columnas
A1: Transacción Columnas | B1: Código Sector Columna | C1: Sector Columna
A2: Demanda intermedia | B2: 1 | C2: Agropecuario-silvícola y Pesca
A3: Demanda intermedia | B3: 2 | C3: Minería
A4: Demanda intermedia | B4: 3 | C4: Industria manufacturera
A5: Demanda intermedia | B5: 4 | C5: Electricidad, gas, agua y gestión de desechos
A6: Demanda intermedia | B6: 5 | C6: Construcción
A7: Demanda intermedia | B7: 6 | C7: Comercio, hoteles y restaurantes
A8: Demanda intermedia | B8: 7 | C8: Transporte, comunicaciones y servicios de información
A9: Demanda intermedia | B9: 8 | C9: Intermediación financiera
A10: Demanda intermedia | B10: 9 | C10: Servicios inmobiliarios y de vivienda
A11: Demanda intermedia | B11: 10 | C11: Servicios empresariales
A12: Demanda intermedia | B12: 11 | C12: Servicios personales
A13: Demanda intermedia | B13: 12 | C13: Administración pública
A14: Consumo de hogares | B14: Ninguno | C14: Ninguno
A15: Consumo de IPSFL | B15: Ninguno | C15: Ninguno
A16: Consumo de gobierno | B16: Ninguno | C16: Ninguno
A17: Formación bruta de capital fijo | B17: Ninguno | C17: Ninguno
A18: Variación de existencias | B18: Ninguno | C18: Ninguno
A19: Exportaciones | B19: Ninguno | C19: Ninguno
A20: Demanda intermedia | B20: 1 | C20: Agropecuario-silvícola y Pesca
A21: Demanda intermedia | B21: 2 | C21: Minería
A22: Demanda intermedia | B22: 3 | C22: Industria manufacturera
A23: Demanda intermedia | B23: 4 | C23: Electricidad, gas, agua y gestión de desechos
A24: Demanda intermedia | B24: 5 | C24: Construcción
A25: Demanda intermedia | B25: 6 | C25: Comercio, hoteles y restaurantes
A26: Demanda intermedia | B26: 7 | C26: Transporte, comunicaciones y servicios de información
A27: Demanda intermedia | B27: 8 | C27: Intermediación financiera
A28: Demanda intermedia | B28: 9 | C28: Servicios inmobiliarios y de vivienda
A29: Demanda intermedia | B29: 10 | C29: Servicios empresariales
A30: Demanda intermedia | B30: 11 | C30: Servicios personales
A31: Demanda intermedia | B31: 12 | C31: Administración pública
A32: Consumo de hogares | B32: Ninguno | C32: Ninguno
A33: Consumo de IPSFL | B33: Ninguno | C33: Ninguno
A34: Consumo de gobierno | B34: Ninguno | C34: Ninguno
A35: Formación bruta de capital fijo | B35: Ninguno | C35: Ninguno
A36: Variación de existencias | B36: Ninguno | C36: Ninguno
A37: Exportaciones | B37: Ninguno | C37: Ninguno
A38: Demanda intermedia | B38: 1 | C38: Agropecuario-silvícola y Pesca
A39: Demanda intermedia | B39: 2 | C39: Minería
A40: Demanda intermedia | B40: 3 | C40: Industria manufacturera
...

Sheet Bioeconomía
A1: 1 | B1: Agropecuario-silvícola y Pesca | C1: Bioeconomía
A2: 2 | B2: Minería | C2: No Bioeconomía
A3: 3 | B3: Industria manufacturera | C3: No Bioeconomía
A4: 4 | B4: Electricidad, gas, agua y gestión de desechos | C4: No Bioeconomía
A5: 5 | B5: Construcción | C5: No Bioeconomía
A6: 6 | B6: Comercio, hoteles y restaurantes | C6: No Bioeconomía
A7: 7 | B7: Transporte, comunicaciones y servicios de información | C7: No Bioeconomía
A8: 8 | B8: Intermediación financiera | C8: No Bioeconomía
A9: 9 | B9: Servicios inmobiliarios y de vivienda | C9: No Bioeconomía
A10: 10 | B10: Servicios empresariales | C10: Bioeconomía extendida
A11: 11 | B11: Servicios personales | C11: No Bioeconomía
A12: 12 | B12: Administración pública | C12: No Bioeconomía
A13: Ninguno | B13: Ninguno | C13: Ninguno

Sheet Nuevo Cuadro Dinámico
A3: Suma de Valor | B3: Etiquetas de columna
B4: Demanda intermedia | E4: Consumo de IPSFL | F4: Consumo de gobierno | G4: Consumo de hogares | H4: Exportaciones | I4: Formación bruta de capital fijo | J4: Variación de existencias | K4: Total general
A5: Etiquetas de fila | B5: Bioeconomía | C5: Bioeconomía extendida | D5: No Bioeconomía | E5: Ninguno | F5: Ninguno | G5: Ninguno | H5: Ninguno | I5: Ninguno | J5: Ninguno
A6: Bioeconomía | B6: 4115.2532 | C6: 6.0921412 | D6: 12372.143 | E6: 0 | F6: 0.02668751 | G6: 2783.6759 | H6: 3460.4746 | I6: 790.68687 | J6: -133.35792 | K6: 23394.995
A7: Bioeconomía extendida | B7: 749.34541 | C7: 4585.6626 | D7: 24505.483 | E7: 0 | F7: 73.289574 | G7: 1570.0364 | H7: 1232.2601 | I7: 4072.6307 | J7: 0.00051274778 | K7: 36788.709
A8: No Bioeconomía | B8: 7375.5613 | C8: 5296.0041 | D8: 127693.99 | E8: 1392.238 | F8: 38220.663 | G8: 114839.82 | H8: 85929.027 | I8: 43515.825 | J8: -618.50437 | K8: 423644.63
A9: Total general | B9: 12240.16 | C9: 9887.7589 | D9: 164571.62 | E9: 1392.238 | F9: 38293.979 | G9: 119193.54 | H9: 90621.762 | I9: 48379.142 | J9: -751.86178 | K9: 483828.33
