Workbook

Sheet columnas
A1: Columnas | B1: Código Transacciones | C1: Área transaccional columnas No. | D1: Área transaccional | E1: Transacciones | F1: Correlativo Transacciones Agregadas | G1: Código Transacciones Agregadas | H1: Transacciones Agregadas | I1: Código Clasificación Actividades | J1: Descripción Actividades | K1: CIIU Secciones | L1: CIIU Secciones descripción | M1: CIIU Corto | N1: CIIU English | O1: Correlativo Bioeconomía Actividades | P1: Bioeconomía Actividades
A2: CHLoc001 | B2: P10 | C2: =+VLOOKUP(B2,'transacciones '!$A$2:$I$39,2,FALSE) -> ATC01 | D2: =+VLOOKUP(B2,'transacciones '!$A$2:$I$39,3,FALSE) -> Producción / Consumo intermedio | E2: =+VLOOKUP(B2,'transacciones '!$A$2:$I$39,4,FALSE) -> Producción | F2: =+VLOOKUP(B2,'transacciones '!$A$2:$I$39,5,FALSE) -> 1 | G2: =+VLOOKUP(B2,'transacciones '!$A$2:$I$39,6,FALSE) -> P1 | H2: =+VLOOKUP(B2,'transacciones '!$A$2:$I$39,7,FALSE) -> Producción | I2: 1 | J2: Cultivos anuales (cereales y otros) y forrajeras | K2: A | L2: =+VLOOKUP(K2,'Correl CIIU'!$A$1:$F$26,2,FALSE) -> Agricultura, ganadería, silvicultura y pesca | M2: =+VLOOKUP(K2,'Correl CIIU'!$A$1:$F$26,3,FALSE) -> Agricultura | N2: =+VLOOKUP(K2,'Correl CIIU'!$A$1:$F$26,4,FALSE) -> Agriculture, forestry and fishing | O2: 1 | P2: =+VLOOKUP(O2,bio!$A$2:$B$4,2,FALSE) -> Bioeconomía
A3: CHLoc002 | B3: P10 | C3: =+VLOOKUP(B3,'transacciones '!$A$2:$I$39,2,FALSE) -> ATC01 | D3: =+VLOOKUP(B3,'transacciones '!$A$2:$I$39,3,FALSE) -> Producción / Consumo intermedio | E3: =+VLOOKUP(B3,'transacciones '!$A$2:$I$39,4,FALSE) -> Producción | F3: =+VLOOKUP(B3,'transacciones '!$A$2:$I$39,5,FALSE) -> 1 | G3: =+VLOOKUP(B3,'transacciones '!$A$2:$I$39,6,FALSE) -> P1 | H3: =+VLOOKUP(B3,'transacciones '!$A$2:$I$39,7,FALSE) -> Producción | I3: 2 | J3: Cultivo de hortalizas y productos de viveros | K3: A | L3: =+VLOOKUP(K3,'Correl CIIU'!$A$1:$F$26,2,FALSE) -> Agricultura, ganadería, silvicultura y pesca | M3: =+VLOOKUP(K3,'Correl CIIU'!$A$1:$F$26,3,FALSE) -> Agricultura | N3: =+VLOOKUP(K3,'Correl CIIU'!$A$1:$F$26,4,FALSE) -> Agriculture, forestry and fishing | O3: 1 | P3: =+VLOOKUP(O3,bio!$A$2:$B$4,2,FALSE) -> Bioeconomía
A4: CHLoc003 | B4: P10 | C4: =+VLOOKUP(B4,'transacciones '!$A$2:$I$39,2,FALSE) -> ATC01 | D4: =+VLOOKUP(B4,'transacciones '!$A$2:$I$39,3,FALSE) -> Producción / Consumo intermedio | E4: =+VLOOKUP(B4,'transacciones '!$A$2:$I$39,4,FALSE) -> Producción | F4: =+VLOOKUP(B4,'transacciones '!$A$2:$I$39,5,FALSE) -> 1 | G4: =+VLOOKUP(B4,'transacciones '!$A$2:$I$39,6,FALSE) -> P1 | H4: =+VLOOKUP(B4,'transacciones '!$A$2:$I$39,7,FALSE) -> Producción | I4: 3 | J4: Cultivo de uva | K4: A | L4: =+VLOOKUP(K4,'Correl CIIU'!$A$1:$F$26,2,FALSE) -> Agricultura, ganadería, silvicultura y pesca | M4: =+VLOOKUP(K4,'Correl CIIU'!$A$1:$F$26,3,FALSE) -> Agricultura | N4: =+VLOOKUP(K4,'Correl CIIU'!$A$1:$F$26,4,FALSE) -> Agriculture, forestry and fishing | O4: 1 | P4: =+VLOOKUP(O4,bio!$A$2:$B$4,2,FALSE) -> Bioeconomía
A5: CHLoc004 | B5: P10 | C5: =+VLOOKUP(B5,'transacciones '!$A$2:$I$39,2,FALSE) -> ATC01 | D5: =+VLOOKUP(B5,'transacciones '!$A$2:$I$39,3,FALSE) -> Producción / Consumo intermedio | E5: =+VLOOKUP(B5,'transacciones '!$A$2:$I$39,4,FALSE) -> Producción | F5: =+VLOOKUP(B5,'transacciones '!$A$2:$I$39,5,FALSE) -> 1 | G5: =+VLOOKUP(B5,'transacciones '!$A$2:$I$39,6,FALSE) -> P1 | H5: =+VLOOKUP(B5,'transacciones '!$A$2:$I$39,7,FALSE) -> Producción | I5: 4 | J5: Cultivo de otras frutas | K5: A | L5: =+VLOOKUP(K5,'Correl CIIU'!$A$1:$F$26,2,FALSE) -> Agricultura, ganadería, silvicultura y pesca | M5: =+VLOOKUP(K5,'Correl CIIU'!$A$1:$F$26,3,FALSE) -> Agricultura | N5: =+VLOOKUP(K5,'Correl CIIU'!$A$1:$F$26,4,FALSE) -> Agriculture, forestry and fishing | O5: 1 | P5: =+VLOOKUP(O5,bio!$A$2:$B$4,2,FALSE) -> Bioeconomía
A6: CHLoc005 | B6: P10 | C6: =+VLOOKUP(B6,'transacciones '!$A$2:$I$39,2,FALSE) -> ATC01 | D6: =+VLOOKUP(B6,'transacciones '!$A$2:$I$39,3,FALSE) -> Producción / Consumo intermedio | E6: =+VLOOKUP(B6,'transacciones '!$A$2:$I$39,4,FALSE) -> Producción | F6: =+VLOOKUP(B6,'transacciones '!$A$2:$I$39,5,FALSE) -> 1 | G6: =+VLOOKUP(B6,'transacciones '!$A$2:$I$39,6,FALSE) -> P1 | H6: =+VLOOKUP(B6,'transacciones '!$A$2:$I$39,7,FALSE) -> Producción | I6: 5 | J6: Cría de ganado bovino | K6: A | L6: =+VLOOKUP(K6,'Correl CIIU'!$A$1:$F$26,2,FALSE) -> Agricultura, ganadería, silvicultura y pesca | M6: =+VLOOKUP(K6,'Correl CIIU'!$A$1:$F$26,3,FALSE) -> Agricultura | N6: =+VLOOKUP(K6,'Correl CIIU'!$A$1:$F$26,4,FALSE) -> Agriculture, forestry and fishing | O6: 1 | P6: =+VLOOKUP(O6,bio!$A$2:$B$4,2,FALSE) -> Bioeconomía
A7: CHLoc006 | B7: P10 | C7: =+VLOOKUP(B7,'transacciones '!$A$2:$I$39,2,FALSE) -> ATC01 | D7: =+VLOOKUP(B7,'transacciones '!$A$2:$I$39,3,FALSE) -> Producción / Consumo intermedio | E7: =+VLOOKUP(B7,'transacciones '!$A$2:$I$39,4,FALSE) -> Producción | F7: =+VLOOKUP(B7,'transacciones '!$A$2:$I$39,5,FALSE) -> 1 | G7: =+VLOOKUP(B7,'transacciones '!$A$2:$I$39,6,FALSE) -> P1 | H7: =+VLOOKUP(B7,'transacciones '!$A$2:$I$39,7,FALSE) -> Producción | I7: 6 | J7: Cría de cerdos | K7: A | L7: =+VLOOKUP(K7,'Correl CIIU'!$A$1:$F$26,2,FALSE) -> Agricultura, ganadería, silvicultura y pesca | M7: =+VLOOKUP(K7,'Correl CIIU'!$A$1:$F$26,3,FALSE) -> Agricultura | N7: =+VLOOKUP(K7,'Correl CIIU'!$A$1:$F$26,4,FALSE) -> Agriculture, forestry and fishing | O7: 1 | P7: =+VLOOKUP(O7,bio!$A$2:$B$4,2,FALSE) -> Bioeconomía
A8: CHLoc007 | B8: P10 | C8: =+VLOOKUP(B8,'transacciones '!$A$2:$I$39,2,FALSE) -> ATC01 | D8: =+VLOOKUP(B8,'transacciones '!$A$2:$I$39,3,FALSE) -> Producción / Consumo intermedio | E8: =+VLOOKUP(B8,'transacciones '!$A$2:$I$39,4,FALSE) -> Producción | F8: =+VLOOKUP(B8,'transacciones '!$A$2:$I$39,5,FALSE) -> 1 | G8: =+VLOOKUP(B8,'transacciones '!$A$2:$I$39,6,FALSE) -> P1 | H8: =+VLOOKUP(B8,'transacciones '!$A$2:$I$39,7,FALSE) -> Producción | I8: 7 | J8: Cría de aves de corral | K8: A | L8: =+VLOOKUP(K8,'Correl CIIU'!$A$1:$F$26,2,FALSE) -> Agricultura, ganadería, silvicultura y pesca | M8: =+VLOOKUP(K8,'Correl CIIU'!$A$1:$F$26,3,FALSE) -> Agricultura | N8: =+VLOOKUP(K8,'Correl CIIU'!$A$1:$F$26,4,FALSE) -> Agriculture, forestry and fishing | O8: 1 | P8: =+VLOOKUP(O8,bio!$A$2:$B$4,2,FALSE) -> Bioeconomía
A9: CHLoc008 | B9: P10 | C9: =+VLOOKUP(B9,'transacciones '!$A$2:$I$39,2,FALSE) -> ATC01 | D9: =+VLOOKUP(B9,'transacciones '!$A$2:$I$39,3,FALSE) -> Producción / Consumo intermedio | E9: =+VLOOKUP(B9,'transacciones '!$A$2:$I$39,4,FALSE) -> Producción | F9: =+VLOOKUP(B9,'transacciones '!$A$2:$I$39,5,FALSE) -> 1 | G9: =+VLOOKUP(B9,'transacciones '!$A$2:$I$39,6,FALSE) -> P1 | H9: =+VLOOKUP(B9,'transacciones '!$A$2:$I$39,7,FALSE) -> Producción | I9: 8 | J9: Cría de otros animales | K9: A | L9: =+VLOOKUP(K9,'Correl CIIU'!$A$1:$F$26,2,FALSE) -> Agricultura, ganadería, silvicultura y pesca | M9: =+VLOOKUP(K9,'Correl CIIU'!$A$1:$F$26,3,FALSE) -> Agricultura | N9: =+VLOOKUP(K9,'Correl CIIU'!$A$1:$F$26,4,FALSE) -> Agriculture, forestry and fishing | O9: 1 | P9: =+VLOOKUP(O9,bio!$A$2:$B$4,2,FALSE) -> Bioeconomía
A10: CHLoc009 | B10: P10 | C10: =+VLOOKUP(B10,'transacciones '!$A$2:$I$39,2,FALSE) -> ATC01 | D10: =+VLOOKUP(B10,'transacciones '!$A$2:$I$39,3,FALSE) -> Producción / Consumo intermedio | E10: =+VLOOKUP(B10,'transacciones '!$A$2:$I$39,4,FALSE) -> Producción | F10: =+VLOOKUP(B10,'transacciones '!$A$2:$I$39,5,FALSE) -> 1 | G10: =+VLOOKUP(B10,'transacciones '!$A$2:$I$39,6,FALSE) -> P1 | H10: =+VLOOKUP(B10,'transacciones '!$A$2:$I$39,7,FALSE) -> Producción | I10: 9 | J10: Actividades de apoyo a la agricultura y ganadería | K10: A | L10: =+VLOOKUP(K10,'Correl CIIU'!$A$1:$F$26,2,FALSE) -> Agricultura, ganadería, silvicultura y pesca | M10: =+VLOOKUP(K10,'Correl CIIU'!$A$1:$F$26,3,FALSE) -> Agricultura | N10: =+VLOOKUP(K10,'Correl CIIU'!$A$1:$F$26,4,FALSE) -> Agriculture, forestry and fishing | O10: 1 | P10: =+VLOOKUP(O10,bio!$A$2:$B$4,2,FALSE) -> Bioeconomía
A11: CHLoc010 | B11: P10 | C11: =+VLOOKUP(B11,'transacciones '!$A$2:$I$39,2,FALSE) -> ATC01 | D11: =+VLOOKUP(B11,'transacciones '!$A$2:$I$39,3,FALSE) -> Producción / Consumo intermedio | E11: =+VLOOKUP(B11,'transacciones '!$A$2:$I$39,4,FALSE) -> Producción | F11: =+VLOOKUP(B11,'transacciones '!$A$2:$I$39,5,FALSE) -> 1 | G11: =+VLOOKUP(B11,'transacciones '!$A$2:$I$39,6,FALSE) -> P1 | H11: =+VLOOKUP(B11,'transacciones '!$A$2:$I$39,7,FALSE) -> Producción | I11: 10 | J11: Silvicultura y extracción de madera | K11: A | L11: =+VLOOKUP(K11,'Correl CIIU'!$A$1:$F$26,2,FALSE) -> Agricultura, ganadería, silvicultura y pesca | M11: =+VLOOKUP(K11,'Correl CIIU'!$A$1:$F$26,3,FALSE) -> Agricultura | N11: =+VLOOKUP(K11,'Correl CIIU'!$A$1:$F$26,4,FALSE) -> Agriculture, forestry and fishing | O11: 1 | P11: =+VLOOKUP(O11,bio!$A$2:$B$4,2,FALSE) -> Bioeconomía
A12: CHLoc011 | B12: P10 | C12: =+VLOOKUP(B12,'transacciones '!$A$2:$I$39,2,FALSE) -> ATC01 | D12: =+VLOOKUP(B12,'transacciones '!$A$2:$I$39,3,FALSE) -> Producción / Consumo intermedio | E12: =+VLOOKUP(B12,'transacciones '!$A$2:$I$39,4,FALSE) -> Producción | F12: =+VLOOKUP(B12,'transacciones '!$A$2:$I$39,5,FALSE) -> 1 | G12: =+VLOOKUP(B12,'transacciones '!$A$2:$I$39,6,FALSE) -> P1 | H12: =+VLOOKUP(B12,'transacciones '!$A$2:$I$39,7,FALSE) -> Producción | I12: 11 | J12: Acuicultura | K12: A | L12: =+VLOOKUP(K12,'Correl CIIU'!$A$1:$F$26,2,FALSE) -> Agricultura, ganadería, silvicultura y pesca | M12: =+VLOOKUP(K12,'Correl CIIU'!$A$1:$F$26,3,FALSE) -> Agricultura | N12: =+VLOOKUP(K12,'Correl CIIU'!$A$1:$F$26,4,FALSE) -> Agriculture, forestry and fishing | O12: 1 | P12: =+VLOOKUP(O12,bio!$A$2:$B$4,2,FALSE) -> Bioeconomía
A13: CHLoc012 | B13: P10 | C13: =+VLOOKUP(B13,'transacciones '!$A$2:$I$39,2,FALSE) -> ATC01 | D13: =+VLOOKUP(B13,'transacciones '!$A$2:$I$39,3,FALSE) -> Producción / Consumo intermedio | E13: =+VLOOKUP(B13,'transacciones '!$A$2:$I$39,4,FALSE) -> Producción | F13: =+VLOOKUP(B13,'transacciones '!$A$2:$I$39,5,FALSE) -> 1 | G13: =+VLOOKUP(B13,'transacciones '!$A$2:$I$39,6,FALSE) -> P1 | H13: =+VLOOKUP(B13,'transacciones '!$A$2:$I$39,7,FALSE) -> Producción | I13: 12 | J13: Pesca extractiva | K13: A | L13: =+VLOOKUP(K13,'Correl CIIU'!$A$1:$F$26,2,FALSE) -> Agricultura, ganadería, silvicultura y pesca | M13: =+VLOOKUP(K13,'Correl CIIU'!$A$1:$F$26,3,FALSE) -> Agricultura | N13: =+VLOOKUP(K13,'Correl CIIU'!$A$1:$F$26,4,FALSE) -> Agriculture, forestry and fishing | O13: 1 | P13: =+VLOOKUP(O13,bio!$A$2:$B$4,2,FALSE) -> Bioeconomía
... A112: CHLoc111 | B112: P10 | C112: =+VLOOKUP(B112,'transacciones '!$A$2:$I$39,2,FALSE) -> ATC01 | D112: =+VLOOKUP(B112,'transacciones '!$A$2:$I$39,3,FALSE) -> Producción / Consumo intermedio | E112: =+VLOOKUP(B112,'transacciones '!$A$2:$I$39,4,FALSE) -> Producción | F112: =+VLOOKUP(B112,'transacciones '!$A$2:$I$39,5,FALSE) -> 1 | G112: =+VLOOKUP(B112,'transacciones '!$A$2:$I$39,6,FALSE) -> P1 | H112: =+VLOOKUP(B112,'transacciones '!$A$2:$I$39,7,FALSE) -> Producción | I112: 111 | J112: Otras actividades de servicios personales | K112: S | L112: =+VLOOKUP(K112,'Correl CIIU'!$A$1:$F$26,2,FALSE) -> Otras actividades de servicios | M112: =+VLOOKUP(K112,'Correl CIIU'!$A$1:$F$26,3,FALSE) -> Otros servicios | N112: =+VLOOKUP(K112,'Correl CIIU'!$A$1:$F$26,4,FALSE) -> Other service activities | O112: 3 | P112: =+VLOOKUP(O112,bio!$A$2:$B$4,2,FALSE) -> No bioeconomía
A113: CHLoc112 | I113: Total | J113: Total
A114: CHLoc113 | I114: Producto | J114: Producto
A115: CHLoc114 | I115: Producción bruta precio básico | J115: Producción bruta precio básico
A116: CHLoc115 | B116: P70 | C116: =+VLOOKUP(B116,'transacciones '!$A$2:$I$39,2,FALSE) -> ATC02 | D116: =+VLOOKUP(B116,'transacciones '!$A$2:$I$39,3,FALSE) -> Exportaciones / Importaciones | E116: =+VLOOKUP(B116,'transacciones '!$A$2:$I$39,4,FALSE) -> Importaciones de bienes Y SERVICIOS | F116: =+VLOOKUP(B116,'transacciones '!$A$2:$I$39,5,FALSE) -> 0 | G116: =+VLOOKUP(B116,'transacciones '!$A$2:$I$39,6,FALSE) -> P7 | H116: =+VLOOKUP(B116,'transacciones '!$A$2:$I$39,7,FALSE) -> Importaciones de bienes y servicios | I116: Importaciones precios cif | J116: Importaciones precios cif | K116: - | L116: - | M116: - | N116: - | O116: - | P116: -
A117: CHLoc116 | I117: Oferta total precio básico | J117: Oferta total precio básico
A118: CHLoc117 | B118: D214 | C118: =+VLOOKUP(B118,'transacciones '!$A$2:$I$39,2,FALSE) -> ATC04 | D118: =+VLOOKUP(B118,'transacciones '!$A$2:$I$39,3,FALSE) -> Impuestos menos subvenciones sobre los productos | E118: =+VLOOKUP(B118,'transacciones '!$A$2:$I$39,4,FALSE) -> Impuestos sobre los productos, excepto IVA e impuestos sobre las importaciones | F118: =+VLOOKUP(B118,'transacciones '!$A$2:$I$39,5,FALSE) -> 9 | G118: =+VLOOKUP(B118,'transacciones '!$A$2:$I$39,6,FALSE) -> D2 | H118: =+VLOOKUP(B118,'transacciones '!$A$2:$I$39,7,FALSE) -> Impuestos sobre la producción y las importaciones | I118: Impuestos indirectos sobre bienes y servicios | J118: Impuestos indirectos sobre bienes y servicios | K118: - | L118: - | M118: - | N118: - | O118: - | P118: -
A119: CHLoc118 | B119: D212 | C119: =+VLOOKUP(B119,'transacciones '!$A$2:$I$39,2,FALSE) -> ATC04 | D119: =+VLOOKUP(B119,'transacciones '!$A$2:$I$39,3,FALSE) -> Impuestos menos subvenciones sobre los productos | E119: =+VLOOKUP(B119,'transacciones '!$A$2:$I$39,4,FALSE) -> Impuestos y derechos sobre las importaciones excepto IVA | F119: =+VLOOKUP(B119,'transacciones '!$A$2:$I$39,5,FALSE) -> 9 | G119: =+VLOOKUP(B119,'transacciones '!$A$2:$I$39,6,FALSE) -> D2 | H119: =+VLOOKUP(B119,'transacciones '!$A$2:$I$39,7,FALSE) -> Impuestos sobre la producción y las importaciones | I119: Derechos de importación | J119: Derechos de importación | K119: - | L119: - | M119: - | N119: - | O119: - | P119: -
A120: CHLoc119 | I120: Oferta total precio productor | J120: Oferta total precio productor
A121: CHLoc120 | B121: M11 | C121: =+VLOOKUP(B121,'transacciones '!$A$2:$I$39,2,FALSE) -> ATC05 | D121: =+VLOOKUP(B121,'transacciones '!$A$2:$I$39,3,FALSE) -> Márgenes de distribución | E121: =+VLOOKUP(B121,'transacciones '!$A$2:$I$39,4,FALSE) -> Márgenes de comercio | F121: =+VLOOKUP(B121,'transacciones '!$A$2:$I$39,5,FALSE) -> 12 | G121: =+VLOOKUP(B121,'transacciones '!$A$2:$I$39,6,FALSE) -> M1 | H121: =+VLOOKUP(B121,'transacciones '!$A$2:$I$39,7,FALSE) -> Márgenes de distribución | I121: Margen de comercio | J121: Margen de comercio | K121: - | L121: - | M121: - | N121: - | O121: - | P121: -
A122: CHLoc121 | B122: D211 | C122: =+VLOOKUP(B122,'transacciones '!$A$2:$I$39,2,FALSE) -> ATC04 | D122: =+VLOOKUP(B122,'transacciones '!$A$2:$I$39,3,FALSE) -> Impuestos menos subvenciones sobre los productos | E122: =+VLOOKUP(B122,'transacciones '!$A$2:$I$39,4,FALSE) -> Impuestos tipo valor agregado (IVA) | F122: =+VLOOKUP(B122,'transacciones '!$A$2:$I$39,5,FALSE) -> 9 | G122: =+VLOOKUP(B122,'transacciones '!$A$2:$I$39,6,FALSE) -> D2 | H122: =+VLOOKUP(B122,'transacciones '!$A$2:$I$39,7,FALSE) -> Impuestos sobre la producción y las importaciones | I122: Impuesto al valor agregado | J122: Impuesto al valor agregado | K122: - | L122: - | M122: - | N122: - | O122: - | P122: -
A123: CHLoc122 | I123: Oferta total precio usuario | J123: Oferta total precio usuario
A124: CHLuc001 | B124: P20 | C124: =+VLOOKUP(B124,'transacciones '!$A$2:$I$39,2,FALSE) -> ATC01 | D124: =+VLOOKUP(B124,'transacciones '!$A$2:$I$39,3,FALSE) -> Producción / Consumo intermedio | E124: =+VLOOKUP(B124,'transacciones '!$A$2:$I$39,4,FALSE) -> Consumo | F124: =+VLOOKUP(B124,'transacciones '!$A$2:$I$39,5,FALSE) -> 2 | G124: =+VLOOKUP(B124,'transacciones '!$A$2:$I$39,6,FALSE) -> P2 | H124: =+VLOOKUP(B124,'transacciones '!$A$2:$I$39,7,FALSE) -> Consumo intermedio | I124: 1 | J124: Cultivos anuales (cereales y otros) y forrajeras | K124: A | L124: =+VLOOKUP(K124,'Correl CIIU'!$A$1:$F$26,2,FALSE) -> Agricultura, ganadería, silvicultura y pesca | M124: =+VLOOKUP(K124,'Correl CIIU'!$A$1:$F$26,3,FALSE) -> Agricultura | N124: =+VLOOKUP(K124,'Correl CIIU'!$A$1:$F$26,4,FALSE) -> Agriculture, forestry and fishing | O124: 1 | P124: =+VLOOKUP(O124,bio!$A$2:$B$4,2,FALSE) -> Bioeconomía
A125: CHLuc002 | B125: P20 | C125: =+VLOOKUP(B125,'transacciones '!$A$2:$I$39,2,FALSE) -> ATC01 | D125: =+VLOOKUP(B125,'transacciones '!$A$2:$I$39,3,FALSE) -> Producción / Consumo intermedio | E125: =+VLOOKUP(B125,'transacciones '!$A$2:$I$39,4,FALSE) -> Consumo | F125: =+VLOOKUP(B125,'transacciones '!$A$2:$I$39,5,FALSE) -> 2 | G125: =+VLOOKUP(B125,'transacciones '!$A$2:$I$39,6,FALSE) -> P2 | H125: =+VLOOKUP(B125,'transacciones '!$A$2:$I$39,7,FALSE) -> Consumo intermedio | I125: 2 | J125: Cultivo de hortalizas y productos de viveros | K125: A | L125: =+VLOOKUP(K125,'Correl CIIU'!$A$1:$F$26,2,FALSE) -> Agricultura, ganadería, silvicultura y pesca | M125: =+VLOOKUP(K125,'Correl CIIU'!$A$1:$F$26,3,FALSE) -> Agricultura | N125: =+VLOOKUP(K125,'Correl CIIU'!$A$1:$F$26,4,FALSE) -> Agriculture, forestry and fishing | O125: 1 | P125: =+VLOOKUP(O125,bio!$A$2:$B$4,2,FALSE) -> Bioeconomía
A126: CHLuc003 | B126: P20 | C126: =+VLOOKUP(B126,'transacciones '!$A$2:$I$39,2,FALSE) -> ATC01 | D126: =+VLOOKUP(B126,'transacciones '!$A$2:$I$39,3,FALSE) -> Producción / Consumo intermedio | E126: =+VLOOKUP(B126,'transacciones '!$A$2:$I$39,4,FALSE) -> Consumo | F126: =+VLOOKUP(B126,'transacciones '!$A$2:$I$39,5,FALSE) -> 2 | G126: =+VLOOKUP(B126,'transacciones '!$A$2:$I$39,6,FALSE) -> P2 | H126: =+VLOOKUP(B126,'transacciones '!$A$2:$I$39,7,FALSE) -> Consumo intermedio | I126: 3 | J126: Cultivo de uva | K126: A | L126: =+VLOOKUP(K126,'Correl CIIU'!$A$1:$F$26,2,FALSE) -> Agricultura, ganadería, silvicultura y pesca | M126: =+VLOOKUP(K126,'Correl CIIU'!$A$1:$F$26,3,FALSE) -> Agricultura | N126: =+VLOOKUP(K126,'Correl CIIU'!$A$1:$F$26,4,FALSE) -> Agriculture, forestry and fishing | O126: 1 | P126: =+VLOOKUP(O126,bio!$A$2:$B$4,2,FALSE) -> Bioeconomía
A127: CHLuc004 | B127: P20 | C127: =+VLOOKUP(B127,'transacciones '!$A$2:$I$39,2,FALSE) -> ATC01 | D127: =+VLOOKUP(B127,'transacciones '!$A$2:$I$39,3,FALSE) -> Producción / Consumo intermedio | E127: =+VLOOKUP(B127,'transacciones '!$A$2:$I$39,4,FALSE) -> Consumo | F127: =+VLOOKUP(B127,'transacciones '!$A$2:$I$39,5,FALSE) -> 2 | G127: =+VLOOKUP(B127,'transacciones '!$A$2:$I$39,6,FALSE) -> P2 | H127: =+VLOOKUP(B127,'transacciones '!$A$2:$I$39,7,FALSE) -> Consumo intermedio | I127: 4 | J127: Cultivo de otras frutas | K127: A | L127: =+VLOOKUP(K127,'Correl CIIU'!$A$1:$F$26,2,FALSE) -> Agricultura, ganadería, silvicultura y pesca | M127: =+VLOOKUP(K127,'Correl CIIU'!$A$1:$F$26,3,FALSE) -> Agricultura | N127: =+VLOOKUP(K127,'Correl CIIU'!$A$1:$F$26,4,FALSE) -> Agriculture, forestry and fishing | O127: 1 | P127: =+VLOOKUP(O127,bio!$A$2:$B$4,2,FALSE) -> Bioeconomía
A128: CHLuc005 | B128: P20 | C128: =+VLOOKUP(B128,'transacciones '!$A$2:$I$39,2,FALSE) -> ATC01 | D128: =+VLOOKUP(B128,'transacciones '!$A$2:$I$39,3,FALSE) -> Producción / Consumo intermedio | E128: =+VLOOKUP(B128,'transacciones '!$A$2:$I$39,4,FALSE) -> Consumo | F128: =+VLOOKUP(B128,'transacciones '!$A$2:$I$39,5,FALSE) -> 2 | G128: =+VLOOKUP(B128,'transacciones '!$A$2:$I$39,6,FALSE) -> P2 | H128: =+VLOOKUP(B128,'transacciones '!$A$2:$I$39,7,FALSE) -> Consumo intermedio | I128: 5 | J128: Cría de ganado bovino | K128: A | L128: =+VLOOKUP(K128,'Correl CIIU'!$A$1:$F$26,2,FALSE) -> Agricultura, ganadería, silvicultura y pesca | M128: =+VLOOKUP(K128,'Correl CIIU'!$A$1:$F$26,3,FALSE) -> Agricultura | N128: =+VLOOKUP(K128,'Correl CIIU'!$A$1:$F$26,4,FALSE) -> Agriculture, forestry and fishing | O128: 1 | P128: =+VLOOKUP(O128,bio!$A$2:$B$4,2,FALSE) -> Bioeconomía
A129: CHLuc006 | B129: P20 | C129: =+VLOOKUP(B129,'transacciones '!$A$2:$I$39,2,FALSE) -> ATC01 | D129: =+VLOOKUP(B129,'transacciones '!$A$2:$I$39,3,FALSE) -> Producción / Consumo intermedio | E129: =+VLOOKUP(B129,'transacciones '!$A$2:$I$39,4,FALSE) -> Consumo | F129: =+VLOOKUP(B129,'transacciones '!$A$2:$I$39,5,FALSE) -> 2 | G129: =+VLOOKUP(B129,'transacciones '!$A$2:$I$39,6,FALSE) -> P2 | H129: =+VLOOKUP(B129,'transacciones '!$A$2:$I$39,7,FALSE) -> Consumo intermedio | I129: 6 | J129: Cría de cerdos | K129: A | L129: =+VLOOKUP(K129,'Correl CIIU'!$A$1:$F$26,2,FALSE) -> Agricultura, ganadería, silvicultura y pesca | M129: =+VLOOKUP(K129,'Correl CIIU'!$A$1:$F$26,3,FALSE) -> Agricultura | N129: =+VLOOKUP(K129,'Correl CIIU'!$A$1:$F$26,4,FALSE) -> Agriculture, forestry and fishing | O129: 1 | P129: =+VLOOKUP(O129,bio!$A$2:$B$4,2,FALSE) -> Bioeconomía
A130: CHLuc007 | B130: P20 | C130: =+VLOOKUP(B130,'transacciones '!$A$2:$I$39,2,FALSE) -> ATC01 | D130: =+VLOOKUP(B130,'transacciones '!$A$2:$I$39,3,FALSE) -> Producción / Consumo intermedio | E130: =+VLOOKUP(B130,'transacciones '!$A$2:$I$39,4,FALSE) -> Consumo | F130: =+VLOOKUP(B130,'transacciones '!$A$2:$I$39,5,FALSE) -> 2 | G130: =+VLOOKUP(B130,'transacciones '!$A$2:$I$39,6,FALSE) -> P2 | H130: =+VLOOKUP(B130,'transacciones '!$A$2:$I$39,7,FALSE) -> Consumo intermedio | I130: 7 | J130: Cría de aves de corral | K130: A | L130: =+VLOOKUP(K130,'Correl CIIU'!$A$1:$F$26,2,FALSE) -> Agricultura, ganadería, silvicultura y pesca | M130: =+VLOOKUP(K130,'Correl CIIU'!$A$1:$F$26,3,FALSE) -> Agricultura | N130: =+VLOOKUP(K130,'Correl CIIU'!$A$1:$F$26,4,FALSE) -> Agriculture, forestry and fishing | O130: 1 | P130: =+VLOOKUP(O130,bio!$A$2:$B$4,2,FALSE) -> Bioeconomía
A131: CHLuc008 | B131: P20 | C131: =+VLOOKUP(B131,'transacciones '!$A$2:$I$39,2,FALSE) -> ATC01 | D131: =+VLOOKUP(B131,'transacciones '!$A$2:$I$39,3,FALSE) -> Producción / Consumo intermedio | E131: =+VLOOKUP(B131,'transacciones '!$A$2:$I$39,4,FALSE) -> Consumo | F131: =+VLOOKUP(B131,'transacciones '!$A$2:$I$39,5,FALSE) -> 2 | G131: =+VLOOKUP(B131,'transacciones '!$A$2:$I$39,6,FALSE) -> P2 | H131: =+VLOOKUP(B131,'transacciones '!$A$2:$I$39,7,FALSE) -> Consumo intermedio | I131: 8 | J131: Cría de otros animales | K131: A | L131: =+VLOOKUP(K131,'Correl CIIU'!$A$1:$F$26,2,FALSE) -> Agricultura, ganadería, silvicultura y pesca | M131: =+VLOOKUP(K131,'Correl CIIU'!$A$1:$F$26,3,FALSE) -> Agricultura | N131: =+VLOOKUP(K131,'Correl CIIU'!$A$1:$F$26,4,FALSE) -> Agriculture, forestry and fishing | O131: 1 | P131: =+VLOOKUP(O131,bio!$A$2:$B$4,2,FALSE) -> Bioeconomía
A132: CHLuc009 | B132: P20 | C132: =+VLOOKUP(B132,'transacciones '!$A$2:$I$39,2,FALSE) -> ATC01 | D132: =+VLOOKUP(B132,'transacciones '!$A$2:$I$39,3,FALSE) -> Producción / Consumo intermedio | E132: =+VLOOKUP(B132,'transacciones '!$A$2:$I$39,4,FALSE) -> Consumo | F132: =+VLOOKUP(B132,'transacciones '!$A$2:$I$39,5,FALSE) -> 2 | G132: =+VLOOKUP(B132,'transacciones '!$A$2:$I$39,6,FALSE) -> P2 | H132: =+VLOOKUP(B132,'transacciones '!$A$2:$I$39,7,FALSE) -> Consumo intermedio | I132: 9 | J132: Actividades de apoyo a la agricultura y ganadería | K132: A | L132: =+VLOOKUP(K132,'Correl CIIU'!$A$1:$F$26,2,FALSE) -> Agricultura, ganadería, silvicultura y pesca | M132: =+VLOOKUP(K132,'Correl CIIU'!$A$1:$F$26,3,FALSE) -> Agricultura | N132: =+VLOOKUP(K132,'Correl CIIU'!$A$1:$F$26,4,FALSE) -> Agriculture, forestry and fishing | O132: 1 | P132: =+VLOOKUP(O132,bio!$A$2:$B$4,2,FALSE) -> Bioeconomía
A133: CHLuc010 | B133: P20 | C133: =+VLOOKUP(B133,'transacciones '!$A$2:$I$39,2,FALSE) -> ATC01 | D133: =+VLOOKUP(B133,'transacciones '!$A$2:$I$39,3,FALSE) -> Producción / Consumo intermedio | E133: =+VLOOKUP(B133,'transacciones '!$A$2:$I$39,4,FALSE) -> Consumo | F133: =+VLOOKUP(B133,'transacciones '!$A$2:$I$39,5,FALSE) -> 2 | G133: =+VLOOKUP(B133,'transacciones '!$A$2:$I$39,6,FALSE) -> P2 | H133: =+VLOOKUP(B133,'transacciones '!$A$2:$I$39,7,FALSE) -> Consumo intermedio | I133: 10 | J133: Silvicultura y extracción de madera | K133: A | L133: =+VLOOKUP(K133,'Correl CIIU'!$A$1:$F$26,2,FALSE) -> Agricultura, ganadería, silvicultura y pesca | M133: =+VLOOKUP(K133,'Correl CIIU'!$A$1:$F$26,3,FALSE) -> Agricultura | N133: =+VLOOKUP(K133,'Correl CIIU'!$A$1:$F$26,4,FALSE) -> Agriculture, forestry and fishing | O133: 1 | P133: =+VLOOKUP(O133,bio!$A$2:$B$4,2,FALSE) -> Bioeconomía
A134: CHLuc011 | B134: P20 | C134: =+VLOOKUP(B134,'transacciones '!$A$2:$I$39,2,FALSE) -> ATC01 | D134: =+VLOOKUP(B134,'transacciones '!$A$2:$I$39,3,FALSE) -> Producción / Consumo intermedio | E134: =+VLOOKUP(B134,'transacciones '!$A$2:$I$39,4,FALSE) -> Consumo | F134: =+VLOOKUP(B134,'transacciones '!$A$2:$I$39,5,FALSE) -> 2 | G134: =+VLOOKUP(B134,'transacciones '!$A$2:$I$39,6,FALSE) -> P2 | H134: =+VLOOKUP(B134,'transacciones '!$A$2:$I$39,7,FALSE) -> Consumo intermedio | I134: 11 | J134: Acuicultura | K134: A | L134: =+VLOOKUP(K134,'Correl CIIU'!$A$1:$F$26,2,FALSE) -> Agricultura, ganadería, silvicultura y pesca | M134: =+VLOOKUP(K134,'Correl CIIU'!$A$1:$F$26,3,FALSE) -> Agricultura | N134: =+VLOOKUP(K134,'Correl CIIU'!$A$1:$F$26,4,FALSE) -> Agriculture, forestry and fishing | O134: 1 | P134: =+VLOOKUP(O134,bio!$A$2:$B$4,2,FALSE) -> Bioeconomía
A135: CHLuc012 | B135: P20 | C135: =+VLOOKUP(B135,'transacciones '!$A$2:$I$39,2,FALSE) -> ATC01 | D135: =+VLOOKUP(B135,'transacciones '!$A$2:$I$39,3,FALSE) -> Producción / Consumo intermedio | E135: =+VLOOKUP(B135,'transacciones '!$A$2:$I$39,4,FALSE) -> Consumo | F135: =+VLOOKUP(B135,'transacciones '!$A$2:$I$39,5,FALSE) -> 2 | G135: =+VLOOKUP(B135,'transacciones '!$A$2:$I$39,6,FALSE) -> P2 | H135: =+VLOOKUP(B135,'transacciones '!$A$2:$I$39,7,FALSE) -> Consumo intermedio | I135: 12 | J135: Pesca extractiva | K135: A | L135: =+VLOOKUP(K135,'Correl CIIU'!$A$1:$F$26,2,FALSE) -> Agricultura, ganadería, silvicultura y pesca | M135: =+VLOOKUP(K135,'Correl CIIU'!$A$1:$F$26,3,FALSE) -> Agricultura | N135: =+VLOOKUP(K135,'Correl CIIU'!$A$1:$F$26,4,FALSE) -> Agriculture, forestry and fishing | O135: 1 | P135: =+VLOOKUP(O135,bio!$A$2:$B$4,2,FALSE) -> Bioeconomía
... A234: CHLuc111 | B234: P20 | C234: =+VLOOKUP(B234,'transacciones '!$A$2:$I$39,2,FALSE) -> ATC01 | D234: =+VLOOKUP(B234,'transacciones '!$A$2:$I$39,3,FALSE) -> Producción / Consumo intermedio | E234: =+VLOOKUP(B234,'transacciones '!$A$2:$I$39,4,FALSE) -> Consumo | F234: =+VLOOKUP(B234,'transacciones '!$A$2:$I$39,5,FALSE) -> 2 | G234: =+VLOOKUP(B234,'transacciones '!$A$2:$I$39,6,FALSE) -> P2 | H234: =+VLOOKUP(B234,'transacciones '!$A$2:$I$39,7,FALSE) -> Consumo intermedio | I234: 111 | J234: Otras actividades de servicios personales | K234: S | L234: =+VLOOKUP(K234,'Correl CIIU'!$A$1:$F$26,2,FALSE) -> Otras actividades de servicios | M234: =+VLOOKUP(K234,'Correl CIIU'!$A$1:$F$26,3,FALSE) -> Otros servicios | N234: =+VLOOKUP(K234,'Correl CIIU'!$A$1:$F$26,4,FALSE) -> Other service activities | O234: 3 | P234: =+VLOOKUP(O234,bio!$A$2:$B$4,2,FALSE) -> No bioeconomía
A235: CHLuc112 | I235: Total | J235: Total
A236: CHLuc113 | I236: Producto | J236: Producto
...

Sheet Correl CIIU
A1: CIIU Secciones | B1: CIIU Secciones descripción | C1: CIIU Corto | D1: CIIU English
A2: A | B2: Agricultura, ganadería, silvicultura y pesca | C2: Agricultura | D2: Agriculture, forestry and fishing
A3: B | B3: Explotación de minas y canteras | C3: Minería | D3: Mining and quarrying
A4: C | B4: Industrias manufactureras | C4: Manufacturas | D4: Manufacturing
A5: C | B5: Industrias manufactureras | C5: Manufacturas | D5: Manufacturing
A6: C | B6: Industrias manufactureras | C6: Manufacturas | D6: Manufacturing
A7: D | B7: Suministro de electricidad, gas, vapor y aire acondicionado | C7: Servicios básicos | D7: Electricity, gas, steam and air conditioning supply
A8: E | B8: Suministro de agua; evacuación de aguas residuales, gestión de desechos y descontaminación | C8: Suministro de agua | D8: Water supply; sewerage, waste management and remediation activities
A9: F | B9: Construcción | C9: Construcción | D9: Construction
A10: G | B10: Comercio al por mayor y al por menor; reparación de vehículos automotores y motocicletas | C10: Comercio | D10: Wholesale and retail trade; repair of motor vehicles and motorcycles
A11: H | B11: Transporte y almacenamiento | C11: Transporte y almacenamiento | D11: Transportation and storage
A12: J | B12: Información y comunicaciones | C12: Información y comunicaciones | D12: Information and communication
... A26: - | B26: - | C26: - | D26: -

Sheet transacciones 
A1: Código Transacciones | B1: Área transaccional columnas No. | C1: Área transaccional | D1: Transacciones | E1: Correlativo Transacciones Agregadas | F1: Código Transacciones Agregadas | G1: Transacciones Agregadas | H1: corr_ntg2 | I1: id_area_columnas
A2: P10 | B2: ATC01 | C2: Producción / Consumo intermedio | D2: Producción | E2: 1 | F2: P1 | G2: Producción | H2: 1 | I2: 0
A3: P11 | B3: ATC01 | C3: Producción / Consumo intermedio | D3: Producción de mercado | E3: 1 | F3: P1 | G3: Producción | H3: 2 | I3: 1
A4: P12 | B4: ATC01 | C4: Producción / Consumo intermedio | D4: Producción para uso final propio | E4: 1 | F4: P1 | G4: Producción | H4: 3 | I4: 2
A5: P13 | B5: ATC01 | C5: Producción / Consumo intermedio | D5: Otra producción no de mercado | E5: 1 | F5: P1 | G5: Producción | H5: 4 | I5: 3
A6: P20 | B6: ATC01 | C6: Producción / Consumo intermedio | D6: Consumo | E6: 2 | F6: P2 | G6: Consumo intermedio | H6: 5 | I6: 0
A7: P21 | B7: ATC01 | C7: Producción / Consumo intermedio | D7: Consumo intermedio de mercado | E7: 2 | F7: P2 | G7: Consumo intermedio | H7: 6 | I7: 1
A8: P22 | B8: ATC01 | C8: Producción / Consumo intermedio | D8: Consumo intermedio para uso final propio | E8: 2 | F8: P2 | G8: Consumo intermedio | H8: 7 | I8: 2
A9: P23 | B9: ATC01 | C9: Producción / Consumo intermedio | D9: Consumo intermedio no de mercado | E9: 2 | F9: P2 | G9: Consumo intermedio | H9: 8 | I9: 3
A10: Pa31 | B10: ATC06 | C10: Gasto de consumo final | D10: Gasto de consumo final de los hogares | E10: 3 | F10: P3 | G10: Gasto de consumo final | H10: 9 | I10: 9
A11: Pb30 | B11: ATC06 | C11: Consumo final | D11: Gasto de consumo ISFLH | E11: 3 | F11: P3 | G11: Gasto de consumo final | H11: 10 | I11: 9
A12: Pb31 | B12: ATC06 | C12: Consumo final | D12: Gasto de consumo individual ISFLSH | E12: 3 | F12: P3 | G12: Gasto de consumo final | H12: 11 | I12: 9
A13: Pb32 | B13: ATC06 | C13: Consumo final | D13: Gasto de consumo colectivo ISFLSH | E13: 3 | F13: P3 | G13: Gasto de consumo final | H13: 12 | I13: 9
A14: Pc30 | B14: ATC06 | C14: Consumo final | D14: Gasto de consumo de gobierno | E14: 3 | F14: P3 | G14: Gasto de consumo final
A15: Pc31 | B15: ATC06 | C15: Consumo final | D15: Gasto de consumo individual de gobierno | E15: 3 | F15: P3 | G15: Gasto de consumo final | H15: 13 | I15: 9
A16: Pc32 | B16: ATC06 | C16: Consumo final | D16: Gasto de consumo colectivo de gobierno | E16: 3 | F16: P3 | G16: Gasto de consumo final | H16: 14 | I16: 9
A17: P41 | B17: ATC06 | C17: Consumo final | D17: Consumo individual efectivo | E17: 4 | F17: P4 | G17: Consumo final efectivo | H17: 15 | I17: 9
A18: P42 | B18: ATC06 | C18: Consumo final | D18: Consumo colectivo efectivo | E18: 4 | F18: P4 | G18: Consumo final efectivo | H18: 16 | I18: 9
A19: P51b | B19: ATC07 | C19: Consumo final | D19: Formación bruta de capital fijo | E19: 5 | F19: P5 | G19: Formación de capital | H19: 17 | I19: 10
A20: P51c | B20: ATC07 | C20: Consumo final | D20: Consumo de capital fijo | E20: 5 | F20: P5 | G20: Formación de capital | H20: 18 | I20: 10
A21: P52 | B21: ATC07 | C21: Consumo final | D21: Variación de existencias | E21: 5 | F21: P5 | G21: Formación de capital | H21: 19 | I21: 10
A22: P53 | B22: ATC07 | C22: Consumo final | D22: Adquisiciones menos disposiciones de objetos valiosos | E22: 5 | F22: P5 | G22: Formación de capital | H22: 20 | I22: 10
A23: P60 | B23: ATC02 | C23: Exportaciones / Importaciones | D23: Exportaciones de bienes y servicios | E23: 6 | F23: P6 | G23: Exportaciones de bienes y servicios | H23: 21 | I23: 4
A24: P61 | B24: ATC02 | C24: Exportaciones / Importaciones | D24: Exportaciones de bienes | E24: 6 | F24: P6 | G24: Exportaciones de bienes y servicios | H24: 22 | I24: 4
A25: P62 | B25: ATC02 | C25: Exportaciones / Importaciones | D25: Exportaciones de servicios | E25: 6 | F25: P6 | G25: Exportaciones de bienes y servicios | H25: 23 | I25: 4
A26: P70 | B26: ATC02 | C26: Exportaciones / Importaciones | D26: Importaciones de bienes Y SERVICIOS | F26: P7 | G26: Importaciones de bienes y servicios | H26: 24 | I26: 4
A27: P71 | B27: ATC02 | C27: Exportaciones / Importaciones | D27: Importaciones de bienes | E27: 7 | F27: P7 | G27: Importaciones de bienes y servicios | H27: 25 | I27: 4
A28: P72 | B28: ATC02 | C28: Exportaciones / Importaciones | D28: Importaciones de servicios | E28: 7 | F28: P7 | G28: Importaciones de bienes y servicios | H28: 26 | I28: 4
A29: CIF | B29: ATC03 | C29: Ajuste CIF/FOB | D29: Ajuste CIF/FOB sobre importaciones | E29: 8 | F29: CIF | G29: Ajuste CIF/FOB sobre importaciones | H29: 27 | I29: 5
A30: D211 | B30: ATC04 | C30: Impuestos menos subvenciones sobre los productos | D30: Impuestos tipo valor agregado (IVA) | E30: 9 | F30: D2 | G30: Impuestos sobre la producción y las importaciones | H30: 28 | I30: 6
A31: D212 | B31: ATC04 | C31: Impuestos menos subvenciones sobre los productos | D31: Impuestos y derechos sobre las importaciones excepto IVA | E31: 9 | F31: D2 | G31: Impuestos sobre la producción y las importaciones | H31: 29 | I31: 6
A32: D213 | B32: ATC04 | C32: Impuestos menos subvenciones sobre los productos | D32: Impuestos sobre las exportaciones | E32: 9 | F32: D2 | G32: Impuestos sobre la producción y las importaciones | H32: 30 | I32: 6
A33: D214 | B33: ATC04 | C33: Impuestos menos subvenciones sobre los productos | D33: Impuestos sobre los productos, excepto IVA e impuestos sobre las importaciones | E33: 9 | F33: D2 | G33: Impuestos sobre la producción y las importaciones | H33: 31 | I33: 6
A34: D291 | B34: ATC04 | C34: Impuestos menos subvenciones sobre los productos | D34: Otros impuestos sobre la producción | E34: 10 | F34: D29 | G34: Otros impuestos sobre la producción | H34: 32 | I34: 6
A35: D31 | B35: ATC04 | C35: Impuestos menos subvenciones sobre los productos | D35: Subvenciones a los productos | E35: 11 | F35: D3 | G35: Subvenciones | H35: 33 | I35: 7
A36: D39 | B36: ATCO4 | C36: Impuestos menos subvenciones sobre los productos | D36: Otras subvenciones a la producción | E36: 11 | F36: D3 | G36: Subvenciones | H36: 34 | I36: 7
A37: M11 | B37: ATC05 | C37: Márgenes de distribución | D37: Márgenes de comercio | E37: 12 | F37: M1 | G37: Márgenes de distribución | H37: 35 | I37: 8
A38: M12 | B38: ATC05 | C38: Márgenes de distribución | D38: Márgenes de transporte | E38: 12 | F38: M1 | G38: Márgenes de distribución | H38: 36 | I38: 8
A39: M13 | B39: ATC05 | C39: Márgenes de distribución | D39: Márgenes de distribución de electricidad | E39: 12 | F39: M1 | G39: Márgenes de distribución | H39: 37 | I39: 8

Sheet bio
A1: Correlativo Bioeconomía Productos | B1: Bioeconomía Productos | D1: Correlativo Bioeconomía Actividades | E1: Bioeconomía Actividades
A2: 1 | B2: Bioeconomía | D2: 1 | E2: Bioeconomía
A3: 2 | B3: Bioeconomía extendida | D3: 2 | E3: Bioeconomía extendida
A4: 3 | B4: No bioeconomía | D4: 3 | E4: No bioeconomía

Sheet at_columnas
A1: Área transaccional columnas No. | B1: Área transaccional | C1: Código Transacciones | D1: Detalle Transacciones
A2: ATC01 | B2: Producción / Consumo intermedio | C2: P11 | D2: Producción de mercado
A3: ATC01 | B3: Producción / Consumo intermedio | C3: P12 | D3: Producción para uso final propio
A4: ATC01 | B4: Producción / Consumo intermedio | C4: P13 | D4: Producción no de mercado
A5: ATC01 | B5: Producción / Consumo intermedio | C5: P21 | D5: Consumo intermedio de mercado
A6: ATC01 | B6: Producción / Consumo intermedio | C6: P22 | D6: Consumo intermedio para uso final propio
A7: ATC01 | B7: Producción / Consumo intermedio | C7: P23 | D7: Consumo intermedio no de mercado
A8: ATC02 | B8: Exportaciones / Importaciones | C8: P6 | D8: Total Exportaciones
A9: ATC02 | B9: Exportaciones / Importaciones | C9: P61 | D9: Exportación de bienes
A10: ATC02 | B10: Exportaciones / Importaciones | C10: P62 | D10: Exportación de servicios
A11: ATC02 | B11: Exportaciones / Importaciones | C11: P7 | D11: Importación de bienes
A12: ATC02 | B12: Exportaciones / Importaciones | C12: P7 | D12: Importación de servicios
... A23: ATC07 | B23: Formación bruta de capital | C23: P52 | D23: Variación de existencias

Sheet filas
A1: Filas | B1: Áreas Transaccionales Filas No. | C1: Áreas Transaccionales Filas Descripción | D1: Codigo Transacción Filas | E1: Código Nomenclatura Local de Productos | F1: Nomenclatura Local de Productos | G1: Código Bioeconomía Productos | H1: Bioeconomía Productos
A2: CHLof001 | B2: ATF01 | C2: =VLOOKUP(B2, AT_FILAS!$A$2:$C$8,2,FALSE) -> Producción | D2: =VLOOKUP(B2, AT_FILAS!$A$2:$C$8,3,FALSE) -> P1 | E2: 1 | F2: Trigo | G2: 1 | H2: =VLOOKUP(G2,[1]bio!$D$2:$E$4,2,FALSE) -> Bioeconomía
A3: CHLof002 | B3: ATF01 | C3: =VLOOKUP(B3, AT_FILAS!$A$2:$C$8,2,FALSE) -> Producción | D3: =VLOOKUP(B3, AT_FILAS!$A$2:$C$8,3,FALSE) -> P1 | E3: 2 | F3: Maíz | G3: 1 | H3: =VLOOKUP(G3,[1]bio!$D$2:$E$4,2,FALSE) -> Bioeconomía
A4: CHLof003 | B4: ATF01 | C4: =VLOOKUP(B4, AT_FILAS!$A$2:$C$8,2,FALSE) -> Producción | D4: =VLOOKUP(B4, AT_FILAS!$A$2:$C$8,3,FALSE) -> P1 | E4: 3 | F4: Otros cereales | G4: 1 | H4: =VLOOKUP(G4,[1]bio!$D$2:$E$4,2,FALSE) -> Bioeconomía
A5: CHLof004 | B5: ATF01 | C5: =VLOOKUP(B5, AT_FILAS!$A$2:$C$8,2,FALSE) -> Producción | D5: =VLOOKUP(B5, AT_FILAS!$A$2:$C$8,3,FALSE) -> P1 | E5: 4 | F5: Tubérculos y legumbres | G5: 1 | H5: =VLOOKUP(G5,[1]bio!$D$2:$E$4,2,FALSE) -> Bioeconomía
A6: CHLof005 | B6: ATF01 | C6: =VLOOKUP(B6, AT_FILAS!$A$2:$C$8,2,FALSE) -> Producción | D6: =VLOOKUP(B6, AT_FILAS!$A$2:$C$8,3,FALSE) -> P1 | E6: 5 | F6: Forrajeras y otros cultivos de uso industrial | G6: 1 | H6: =VLOOKUP(G6,[1]bio!$D$2:$E$4,2,FALSE) -> Bioeconomía
A7: CHLof006 | B7: ATF01 | C7: =VLOOKUP(B7, AT_FILAS!$A$2:$C$8,2,FALSE) -> Producción | D7: =VLOOKUP(B7, AT_FILAS!$A$2:$C$8,3,FALSE) -> P1 | E7: 6 | F7: Hortalizas y setas | G7: 1 | H7: =VLOOKUP(G7,[1]bio!$D$2:$E$4,2,FALSE) -> Bioeconomía
A8: CHLof007 | B8: ATF01 | C8: =VLOOKUP(B8, AT_FILAS!$A$2:$C$8,2,FALSE) -> Producción | D8: =VLOOKUP(B8, AT_FILAS!$A$2:$C$8,3,FALSE) -> P1 | E8: 7 | F8: Uva vinífera y pisquera | G8: 1 | H8: =VLOOKUP(G8,[1]bio!$D$2:$E$4,2,FALSE) -> Bioeconomía
A9: CHLof008 | B9: ATF01 | C9: =VLOOKUP(B9, AT_FILAS!$A$2:$C$8,2,FALSE) -> Producción | D9: =VLOOKUP(B9, AT_FILAS!$A$2:$C$8,3,FALSE) -> P1 | E9: 8 | F9: Uva de mesa | G9: 1 | H9: =VLOOKUP(G9,[1]bio!$D$2:$E$4,2,FALSE) -> Bioeconomía
A10: CHLof009 | B10: ATF01 | C10: =VLOOKUP(B10, AT_FILAS!$A$2:$C$8,2,FALSE) -> Producción | D10: =VLOOKUP(B10, AT_FILAS!$A$2:$C$8,3,FALSE) -> P1 | E10: 9 | F10: Manzanas | G10: 1 | H10: =VLOOKUP(G10,[1]bio!$D$2:$E$4,2,FALSE) -> Bioeconomía
A11: CHLof010 | B11: ATF01 | C11: =VLOOKUP(B11, AT_FILAS!$A$2:$C$8,2,FALSE) -> Producción | D11: =VLOOKUP(B11, AT_FILAS!$A$2:$C$8,3,FALSE) -> P1 | E11: 10 | F11: Duraznos y otros carozos | G11: 1 | H11: =VLOOKUP(G11,[1]bio!$D$2:$E$4,2,FALSE) -> Bioeconomía
A12: CHLof011 | B12: ATF01 | C12: =VLOOKUP(B12, AT_FILAS!$A$2:$C$8,2,FALSE) -> Producción | D12: =VLOOKUP(B12, AT_FILAS!$A$2:$C$8,3,FALSE) -> P1 | E12: 11 | F12: Paltas | G12: 1 | H12: =VLOOKUP(G12,[1]bio!$D$2:$E$4,2,FALSE) -> Bioeconomía
A13: CHLof012 | B13: ATF01 | C13: =VLOOKUP(B13, AT_FILAS!$A$2:$C$8,2,FALSE) -> Producción | D13: =VLOOKUP(B13, AT_FILAS!$A$2:$C$8,3,FALSE) -> P1 | E13: 12 | F13: Kiwis y otras frutas tropicales | G13: 1 | H13: =VLOOKUP(G13,[1]bio!$D$2:$E$4,2,FALSE) -> Bioeconomía
... A363: CHLuf181 | B363: ATF02 | C363: =VLOOKUP(B363, AT_FILAS!$A$2:$C$8,2,FALSE) -> Consumo intermedio | D363: =VLOOKUP(B363, AT_FILAS!$A$2:$C$8,3,FALSE) -> P2 | E363: 181 | F363: Otros bienes y servicios | G363: 3 | H363: =VLOOKUP(G363,[1]bio!$D$2:$E$4,2,FALSE) -> No bioeconomía
A364: CHLvf001 | B364: ATF06 | C364: =VLOOKUP(B364, AT_FILAS!$A$2:$C$8,2,FALSE) -> Valor Agregado | D364: =VLOOKUP(B364, AT_FILAS!$A$2:$C$8,3,FALSE) -> - | E364: - | F364: - | G364: - | H364: -

Sheet AT_FILAS
A1: Áreas Transaccionales Filas No. | B1: Áreas Transaccionales Filas Descripción | C1: Codigo Transacción Filas
A2: ATF01 | B2: Producción | C2: P1
A3: ATF02 | B3: Consumo intermedio | C3: P2
A4: ATF03 | B4: Ajuste CIF/FOB | C4: CIF
A5: ATF04 | B5: Compras directas en el exterior por residentes | C5: P6
A6: ATF05 | B6: Compras directas en el territorio nacional por no residentes | C6: P7
A7: ATF06 | B7: Valor Agregado | C7: -
A8: ATF07 | B8: Puestos de trabajo | C8: -
