Workbook

Sheet Filas
A1: Filas | B1: Áreas Transaccionales Filas No. | C1: Áreas Transaccionales Filas Descripción | D1: Codigo Transacción Filas | E1: Transacción filas | F1: Código Productos (CUP) | G1: Productos (CUP) | H1: Código CPC Grupos | I1: CPC Grupos | J1: Código Productos Compactos | K1: Productos Compactos | L1: Código Bioeconomía Productos | M1: Bioeconomía Productos | N1: Código CUPc | O1: CUPc
A2: mp_f001 | B2: ATF01 | C2: Producción | D2: P1 | E2: Producción | F2: 1 | G2: Trigo | H2: =IF(F2="","",VLOOKUP(F2,Productos!$A$2:$F$182,3,FALSE)) -> 0 | I2: =IF(F2="","",VLOOKUP(F2,Productos!$A$2:$F$182,4,FALSE)) -> Productos de la agricultura, la silvicultura y la pesca | J2: =IF(F2="","",VLOOKUP(F2,Productos!$A$2:$F$182,5,FALSE)) -> 1 | K2: =IF(F2="","",VLOOKUP(F2,Productos!$A$2:$F$182,6,FALSE)) -> Agropecuarios | L2: 1 | M2: Bioeconomía | N2: =VLOOKUP(F2,Productos!$A$2:$J$182,5) -> 1 | O2: =VLOOKUP(F2,Productos!$A$2:$J$182,6) -> Agropecuarios
A3: mp_f002 | B3: ATF01 | C3: Producción | D3: P1 | E3: Producción | F3: 2 | G3: Maíz | H3: =IF(F3="","",VLOOKUP(F3,Productos!$A$2:$F$182,3,FALSE)) -> 0 | I3: =IF(F3="","",VLOOKUP(F3,Productos!$A$2:$F$182,4,FALSE)) -> Productos de la agricultura, la silvicultura y la pesca | J3: =IF(F3="","",VLOOKUP(F3,Productos!$A$2:$F$182,5,FALSE)) -> 1 | K3: =IF(F3="","",VLOOKUP(F3,Productos!$A$2:$F$182,6,FALSE)) -> Agropecuarios | L3: 1 | M3: Bioeconomía | N3: =VLOOKUP(F3,Productos!$A$2:$J$182,5) -> 1 | O3: =VLOOKUP(F3,Productos!$A$2:$J$182,6) -> Agropecuarios
A4: mp_f003 | B4: ATF01 | C4: Producción | D4: P1 | E4: Producción | F4: 3 | G4: Otros cereales | H4: =IF(F4="","",VLOOKUP(F4,Productos!$A$2:$F$182,3,FALSE)) -> 0 | I4: =IF(F4="","",VLOOKUP(F4,Productos!$A$2:$F$182,4,FALSE)) -> Productos de la agricultura, la silvicultura y la pesca | J4: =IF(F4="","",VLOOKUP(F4,Productos!$A$2:$F$182,5,FALSE)) -> 1 | K4: =IF(F4="","",VLOOKUP(F4,Productos!$A$2:$F$182,6,FALSE)) -> Agropecuarios | L4: 1 | M4: Bioeconomía | N4: =VLOOKUP(F4,Productos!$A$2:$J$182,5) -> 1 | O4: =VLOOKUP(F4,Productos!$A$2:$J$182,6) -> Agropecuarios
A5: mp_f004 | B5: ATF01 | C5: Producción | D5: P1 | E5: Producción | F5: 4 | G5: Tubérculos y legumbres | H5: =IF(F5="","",VLOOKUP(F5,Productos!$A$2:$F$182,3,FALSE)) -> 0 | I5: =IF(F5="","",VLOOKUP(F5,Productos!$A$2:$F$182,4,FALSE)) -> Productos de la agricultura, la silvicultura y la pesca | J5: =IF(F5="","",VLOOKUP(F5,Productos!$A$2:$F$182,5,FALSE)) -> 1 | K5: =IF(F5="","",VLOOKUP(F5,Productos!$A$2:$F$182,6,FALSE)) -> Agropecuarios | L5: 1 | M5: Bioeconomía | N5: =VLOOKUP(F5,Productos!$A$2:$J$182,5) -> 1 | O5: =VLOOKUP(F5,Productos!$A$2:$J$182,6) -> Agropecuarios
A6: mp_f005 | B6: ATF01 | C6: Producción | D6: P1 | E6: Producción | F6: 5 | G6: Forrajeras y otros cultivos de uso industrial | H6: =IF(F6="","",VLOOKUP(F6,Productos!$A$2:$F$182,3,FALSE)) -> 0 | I6: =IF(F6="","",VLOOKUP(F6,Productos!$A$2:$F$182,4,FALSE)) -> Productos de la agricultura, la silvicultura y la pesca | J6: =IF(F6="","",VLOOKUP(F6,Productos!$A$2:$F$182,5,FALSE)) -> 1 | K6: =IF(F6="","",VLOOKUP(F6,Productos!$A$2:$F$182,6,FALSE)) -> Agropecuarios | L6: 1 | M6: Bioeconomía | N6: =VLOOKUP(F6,Productos!$A$2:$J$182,5) -> 1 | O6: =VLOOKUP(F6,Productos!$A$2:$J$182,6) -> Agropecuarios
A7: mp_f006 | B7: ATF01 | C7: Producción | D7: P1 | E7: Producción | F7: 6 | G7: Hortalizas y setas | H7: =IF(F7="","",VLOOKUP(F7,Productos!$A$2:$F$182,3,FALSE)) -> 0 | I7: =IF(F7="","",VLOOKUP(F7,Productos!$A$2:$F$182,4,FALSE)) -> Productos de la agricultura, la silvicultura y la pesca | J7: =IF(F7="","",VLOOKUP(F7,Productos!$A$2:$F$182,5,FALSE)) -> 1 | K7: =IF(F7="","",VLOOKUP(F7,Productos!$A$2:$F$182,6,FALSE)) -> Agropecuarios | L7: 1 | M7: Bioeconomía | N7: =VLOOKUP(F7,Productos!$A$2:$J$182,5) -> 1 | O7: =VLOOKUP(F7,Productos!$A$2:$J$182,6) -> Agropecuarios
A8: mp_f007 | B8: ATF01 | C8: Producción | D8: P1 | E8: Producción | F8: 7 | G8: Uva vinífera y pisquera | H8: =IF(F8="","",VLOOKUP(F8,Productos!$A$2:$F$182,3,FALSE)) -> 0 | I8: =IF(F8="","",VLOOKUP(F8,Productos!$A$2:$F$182,4,FALSE)) -> Productos de la agricultura, la silvicultura y la pesca | J8: =IF(F8="","",VLOOKUP(F8,Productos!$A$2:$F$182,5,FALSE)) -> 1 | K8: =IF(F8="","",VLOOKUP(F8,Productos!$A$2:$F$182,6,FALSE)) -> Agropecuarios | L8: 1 | M8: Bioeconomía | N8: =VLOOKUP(F8,Productos!$A$2:$J$182,5) -> 1 | O8: =VLOOKUP(F8,Productos!$A$2:$J$182,6) -> Agropecuarios
A9: mp_f008 | B9: ATF01 | C9: Producción | D9: P1 | E9: Producción | F9: 8 | G9: Uva de mesa | H9: =IF(F9="","",VLOOKUP(F9,Productos!$A$2:$F$182,3,FALSE)) -> 0 | I9: =IF(F9="","",VLOOKUP(F9,Productos!$A$2:$F$182,4,FALSE)) -> Productos de la agricultura, la silvicultura y la pesca | J9: =IF(F9="","",VLOOKUP(F9,Productos!$A$2:$F$182,5,FALSE)) -> 1 | K9: =IF(F9="","",VLOOKUP(F9,Productos!$A$2:$F$182,6,FALSE)) -> Agropecuarios | L9: 1 | M9: Bioeconomía | N9: =VLOOKUP(F9,Productos!$A$2:$J$182,5) -> 1 | O9: =VLOOKUP(F9,Productos!$A$2:$J$182,6) -> Agropecuarios
A10: mp_f009 | B10: ATF01 | C10: Producción | D10: P1 | E10: Producción | F10: 9 | G10: Manzanas | H10: =IF(F10="","",VLOOKUP(F10,Productos!$A$2:$F$182,3,FALSE)) -> 0 | I10: =IF(F10="","",VLOOKUP(F10,Productos!$A$2:$F$182,4,FALSE)) -> Productos de la agricultura, la silvicultura y la pesca | J10: =IF(F10="","",VLOOKUP(F10,Productos!$A$2:$F$182,5,FALSE)) -> 1 | K10: =IF(F10="","",VLOOKUP(F10,Productos!$A$2:$F$182,6,FALSE)) -> Agropecuarios | L10: 1 | M10: Bioeconomía | N10: =VLOOKUP(F10,Productos!$A$2:$J$182,5) -> 1 | O10: =VLOOKUP(F10,Productos!$A$2:$J$182,6) -> Agropecuarios
A11: mp_f010 | B11: ATF01 | C11: Producción | D11: P1 | E11: Producción | F11: 10 | G11: Duraznos y otros carozos | H11: =IF(F11="","",VLOOKUP(F11,Productos!$A$2:$F$182,3,FALSE)) -> 0 | I11: =IF(F11="","",VLOOKUP(F11,Productos!$A$2:$F$182,4,FALSE)) -> Productos de la agricultura, la silvicultura y la pesca | J11: =IF(F11="","",VLOOKUP(F11,Productos!$A$2:$F$182,5,FALSE)) -> 1 | K11: =IF(F11="","",VLOOKUP(F11,Productos!$A$2:$F$182,6,FALSE)) -> Agropecuarios | L11: 1 | M11: Bioeconomía | N11: =VLOOKUP(F11,Productos!$A$2:$J$182,5) -> 1 | O11: =VLOOKUP(F11,Productos!$A$2:$J$182,6) -> Agropecuarios
A12: mp_f011 | B12: ATF01 | C12: Producción | D12: P1 | E12: Producción | F12: 11 | G12: Paltas | H12: =IF(F12="","",VLOOKUP(F12,Productos!$A$2:$F$182,3,FALSE)) -> 0 | I12: =IF(F12="","",VLOOKUP(F12,Productos!$A$2:$F$182,4,FALSE)) -> Productos de la agricultura, la silvicultura y la pesca | J12: =IF(F12="","",VLOOKUP(F12,Productos!$A$2:$F$182,5,FALSE)) -> 1 | K12: =IF(F12="","",VLOOKUP(F12,Productos!$A$2:$F$182,6,FALSE)) -> Agropecuarios | L12: 1 | M12: Bioeconomía | N12: =VLOOKUP(F12,Productos!$A$2:$J$182,5) -> 1 | O12: =VLOOKUP(F12,Productos!$A$2:$J$182,6) -> Agropecuarios
A13: mp_f012 | B13: ATF01 | C13: Producción | D13: P1 | E13: Producción | F13: 12 | G13: Kiwis y otras frutas tropicales | H13: =IF(F13="","",VLOOKUP(F13,Productos!$A$2:$F$182,3,FALSE)) -> 0 | I13: =IF(F13="","",VLOOKUP(F13,Productos!$A$2:$F$182,4,FALSE)) -> Productos de la agricultura, la silvicultura y la pesca | J13: =IF(F13="","",VLOOKUP(F13,Productos!$A$2:$F$182,5,FALSE)) -> 1 | K13: =IF(F13="","",VLOOKUP(F13,Productos!$A$2:$F$182,6,FALSE)) -> Agropecuarios | L13: 1 | M13: Bioeconomía | N13: =VLOOKUP(F13,Productos!$A$2:$J$182,5) -> 1 | O13: =VLOOKUP(F13,Productos!$A$2:$J$182,6) -> Agropecuarios
... A725: ut_f181 | B725: ATF02 | C725: Consumo intermedio | D725: P2 | E725: Consumo intermedio | F725: 181 | G725: Otros bienes y servicios | H725: =IF(F725="","",VLOOKUP(F725,Productos!$A$2:$F$182,3,FALSE)) -> 9 | I725: =IF(F725="","",VLOOKUP(F725,Productos!$A$2:$F$182,4,FALSE)) -> Servicios para la comunidad, sociales y personales | J725: =IF(F725="","",VLOOKUP(F725,Productos!$A$2:$F$182,5,FALSE)) -> 7 | K725: =IF(F725="","",VLOOKUP(F725,Productos!$A$2:$F$182,6,FALSE)) -> Otros servicios | L725: 3 | M725: No bioeconomía | N725: =VLOOKUP(F725,Productos!$A$2:$J$182,5) -> 7 | O725: =VLOOKUP(F725,Productos!$A$2:$J$182,6) -> Otros servicios
A726: va_f001 | B726: ATF06 | C726: Valor Agregado | D726: P91 | E726: Remuneraciones | H726: =IF(F726="","",VLOOKUP(F726,Productos!$A$2:$F$182,3,FALSE)) | I726: =IF(F726="","",VLOOKUP(F726,Productos!$A$2:$F$182,4,FALSE)) | J726: =IF(F726="","",VLOOKUP(F726,Productos!$A$2:$F$182,5,FALSE)) | K726: =IF(F726="","",VLOOKUP(F726,Productos!$A$2:$F$182,6,FALSE))
A727: va_f002 | H727: =IF(F727="","",VLOOKUP(F727,Productos!$A$2:$F$182,3,FALSE)) | I727: =IF(F727="","",VLOOKUP(F727,Productos!$A$2:$F$182,4,FALSE)) | J727: =IF(F727="","",VLOOKUP(F727,Productos!$A$2:$F$182,5,FALSE)) | K727: =IF(F727="","",VLOOKUP(F727,Productos!$A$2:$F$182,6,FALSE))
A728: va_f003 | H728: =IF(F728="","",VLOOKUP(F728,Productos!$A$2:$F$182,3,FALSE)) | I728: =IF(F728="","",VLOOKUP(F728,Productos!$A$2:$F$182,4,FALSE)) | J728: =IF(F728="","",VLOOKUP(F728,Productos!$A$2:$F$182,5,FALSE)) | K728: =IF(F728="","",VLOOKUP(F728,Productos!$A$2:$F$182,6,FALSE))
A729: va_f004 | B729: ATF06 | C729: Valor Agregado | D729: P92 | E729: Excedente bruto de explotación | H729: =IF(F729="","",VLOOKUP(F729,Productos!$A$2:$F$182,3,FALSE)) | I729: =IF(F729="","",VLOOKUP(F729,Productos!$A$2:$F$182,4,FALSE)) | J729: =IF(F729="","",VLOOKUP(F729,Productos!$A$2:$F$182,5,FALSE)) | K729: =IF(F729="","",VLOOKUP(F729,Productos!$A$2:$F$182,6,FALSE))
A730: va_f005 | H730: =IF(F730="","",VLOOKUP(F730,Productos!$A$2:$F$182,3,FALSE)) | I730: =IF(F730="","",VLOOKUP(F730,Productos!$A$2:$F$182,4,FALSE)) | J730: =IF(F730="","",VLOOKUP(F730,Productos!$A$2:$F$182,5,FALSE)) | K730: =IF(F730="","",VLOOKUP(F730,Productos!$A$2:$F$182,6,FALSE))
A731: va_f006 | H731: =IF(F731="","",VLOOKUP(F731,Productos!$A$2:$F$182,3,FALSE)) | I731: =IF(F731="","",VLOOKUP(F731,Productos!$A$2:$F$182,4,FALSE)) | J731: =IF(F731="","",VLOOKUP(F731,Productos!$A$2:$F$182,5,FALSE)) | K731: =IF(F731="","",VLOOKUP(F731,Productos!$A$2:$F$182,6,FALSE))
A732: va_f007 | B732: ATF06 | C732: Valor Agregado | D732: P93 | E732: Impuestos netos sobre los productos | H732: =IF(F732="","",VLOOKUP(F732,Productos!$A$2:$F$182,3,FALSE)) | I732: =IF(F732="","",VLOOKUP(F732,Productos!$A$2:$F$182,4,FALSE)) | J732: =IF(F732="","",VLOOKUP(F732,Productos!$A$2:$F$182,5,FALSE)) | K732: =IF(F732="","",VLOOKUP(F732,Productos!$A$2:$F$182,6,FALSE))
A733: va_f008 | H733: =IF(F733="","",VLOOKUP(F733,Productos!$A$2:$F$182,3,FALSE)) | I733: =IF(F733="","",VLOOKUP(F733,Productos!$A$2:$F$182,4,FALSE)) | J733: =IF(F733="","",VLOOKUP(F733,Productos!$A$2:$F$182,5,FALSE)) | K733: =IF(F733="","",VLOOKUP(F733,Productos!$A$2:$F$182,6,FALSE))
A734: va_f009 | H734: =IF(F734="","",VLOOKUP(F734,Productos!$A$2:$F$182,3,FALSE)) | I734: =IF(F734="","",VLOOKUP(F734,Productos!$A$2:$F$182,4,FALSE)) | J734: =IF(F734="","",VLOOKUP(F734,Productos!$A$2:$F$182,5,FALSE)) | K734: =IF(F734="","",VLOOKUP(F734,Productos!$A$2:$F$182,6,FALSE))
A735: va_f010 | B735: ATF06 | C735: Valor Agregado | D735: P94 | E735: Otros impuestos netos sobre la producción | H735: =IF(F735="","",VLOOKUP(F735,Productos!$A$2:$F$182,3,FALSE)) | I735: =IF(F735="","",VLOOKUP(F735,Productos!$A$2:$F$182,4,FALSE)) | J735: =IF(F735="","",VLOOKUP(F735,Productos!$A$2:$F$182,5,FALSE)) | K735: =IF(F735="","",VLOOKUP(F735,Productos!$A$2:$F$182,6,FALSE))

Sheet Columnas
A1: Columnas | B1: Código Transacciones | C1: Transacciones | D1: Código Áreas Transaccionales | E1: Áreas Transaccionales | F1: Código ATC | G1: ATC | H1: Actividades (CAE) | I1: Código CIIU Secciones | J1: CIIU Secciones | K1: CIIU Corto | L1: CIIU English | M1: Correlativo Bioeconomía Actividades | N1: Bioeconomía Actividades | O1: Código CAEc | P1: CAEc
A2: mp_c001 | B2: 1 | C2: =IF(B2="","",VLOOKUP(B2,'Transacciones CHL'!$A$2:$B$14,2,FALSE)) -> Producción bruta precio básico | D2: =IF(B2="","",VLOOKUP(B2,'Transacciones CHL'!$A$2:$F$14,3,FALSE)) -> 1 | E2: =IF(B2="","",VLOOKUP(B2,'Transacciones CHL'!$A$2:$F$14,4,FALSE)) -> Producción / Consumo intermedio | F2: =IF(B2="","",VLOOKUP(B2,'Transacciones CHL'!$A$2:$F$14,5,FALSE)) -> 1 | G2: =IF(B2="","",VLOOKUP(B2,'Transacciones CHL'!$A$2:$F$14,6,FALSE)) -> Producción / Consumo intermedio | H2: Cultivos anuales (cereales y otros) y forrajeras | I2: A | J2: Agricultura, ganadería, silvicultura y pesca | K2: Agricultura | L2: Agriculture, forestry and fishing | M2: 1 | N2: Bioeconomía | O2: 2 | P2: No culturales
A3: mp_c002 | B3: 1 | C3: =IF(B3="","",VLOOKUP(B3,'Transacciones CHL'!$A$2:$B$14,2,FALSE)) -> Producción bruta precio básico | D3: =IF(B3="","",VLOOKUP(B3,'Transacciones CHL'!$A$2:$F$14,3,FALSE)) -> 1 | E3: =IF(B3="","",VLOOKUP(B3,'Transacciones CHL'!$A$2:$F$14,4,FALSE)) -> Producción / Consumo intermedio | F3: =IF(B3="","",VLOOKUP(B3,'Transacciones CHL'!$A$2:$F$14,5,FALSE)) -> 1 | G3: =IF(B3="","",VLOOKUP(B3,'Transacciones CHL'!$A$2:$F$14,6,FALSE)) -> Producción / Consumo intermedio | H3: Cultivo de hortalizas y productos de viveros | I3: A | J3: Agricultura, ganadería, silvicultura y pesca | K3: Agricultura | L3: Agriculture, forestry and fishing | M3: 1 | N3: Bioeconomía | O3: 2 | P3: No culturales
A4: mp_c003 | B4: 1 | C4: =IF(B4="","",VLOOKUP(B4,'Transacciones CHL'!$A$2:$B$14,2,FALSE)) -> Producción bruta precio básico | D4: =IF(B4="","",VLOOKUP(B4,'Transacciones CHL'!$A$2:$F$14,3,FALSE)) -> 1 | E4: =IF(B4="","",VLOOKUP(B4,'Transacciones CHL'!$A$2:$F$14,4,FALSE)) -> Producción / Consumo intermedio | F4: =IF(B4="","",VLOOKUP(B4,'Transacciones CHL'!$A$2:$F$14,5,FALSE)) -> 1 | G4: =IF(B4="","",VLOOKUP(B4,'Transacciones CHL'!$A$2:$F$14,6,FALSE)) -> Producción / Consumo intermedio | H4: Cultivo de uva | I4: A | J4: Agricultura, ganadería, silvicultura y pesca | K4: Agricultura | L4: Agriculture, forestry and fishing | M4: 1 | N4: Bioeconomía | O4: 2 | P4: No culturales
A5: mp_c004 | B5: 1 | C5: =IF(B5="","",VLOOKUP(B5,'Transacciones CHL'!$A$2:$B$14,2,FALSE)) -> Producción bruta precio básico | D5: =IF(B5="","",VLOOKUP(B5,'Transacciones CHL'!$A$2:$F$14,3,FALSE)) -> 1 | E5: =IF(B5="","",VLOOKUP(B5,'Transacciones CHL'!$A$2:$F$14,4,FALSE)) -> Producción / Consumo intermedio | F5: =IF(B5="","",VLOOKUP(B5,'Transacciones CHL'!$A$2:$F$14,5,FALSE)) -> 1 | G5: =IF(B5="","",VLOOKUP(B5,'Transacciones CHL'!$A$2:$F$14,6,FALSE)) -> Producción / Consumo intermedio | H5: Cultivo de otras frutas | I5: A | J5: Agricultura, ganadería, silvicultura y pesca | K5: Agricultura | L5: Agriculture, forestry and fishing | M5: 1 | N5: Bioeconomía | O5: 2 | P5: No culturales
A6: mp_c005 | B6: 1 | C6: =IF(B6="","",VLOOKUP(B6,'Transacciones CHL'!$A$2:$B$14,2,FALSE)) -> Producción bruta precio básico | D6: =IF(B6="","",VLOOKUP(B6,'Transacciones CHL'!$A$2:$F$14,3,FALSE)) -> 1 | E6: =IF(B6="","",VLOOKUP(B6,'Transacciones CHL'!$A$2:$F$14,4,FALSE)) -> Producción / Consumo intermedio | F6: =IF(B6="","",VLOOKUP(B6,'Transacciones CHL'!$A$2:$F$14,5,FALSE)) -> 1 | G6: =IF(B6="","",VLOOKUP(B6,'Transacciones CHL'!$A$2:$F$14,6,FALSE)) -> Producción / Consumo intermedio | H6: Cría de ganado bovino | I6: A | J6: Agricultura, ganadería, silvicultura y pesca | K6: Agricultura | L6: Agriculture, forestry and fishing | M6: 1 | N6: Bioeconomía | O6: 2 | P6: No culturales
A7: mp_c006 | B7: 1 | C7: =IF(B7="","",VLOOKUP(B7,'Transacciones CHL'!$A$2:$B$14,2,FALSE)) -> Producción bruta precio básico | D7: =IF(B7="","",VLOOKUP(B7,'Transacciones CHL'!$A$2:$F$14,3,FALSE)) -> 1 | E7: =IF(B7="","",VLOOKUP(B7,'Transacciones CHL'!$A$2:$F$14,4,FALSE)) -> Producción / Consumo intermedio | F7: =IF(B7="","",VLOOKUP(B7,'Transacciones CHL'!$A$2:$F$14,5,FALSE)) -> 1 | G7: =IF(B7="","",VLOOKUP(B7,'Transacciones CHL'!$A$2:$F$14,6,FALSE)) -> Producción / Consumo intermedio | H7: Cría de cerdos | I7: A | J7: Agricultura, ganadería, silvicultura y pesca | K7: Agricultura | L7: Agriculture, forestry and fishing | M7: 1 | N7: Bioeconomía | O7: 2 | P7: No culturales
A8: mp_c007 | B8: 1 | C8: =IF(B8="","",VLOOKUP(B8,'Transacciones CHL'!$A$2:$B$14,2,FALSE)) -> Producción bruta precio básico | D8: =IF(B8="","",VLOOKUP(B8,'Transacciones CHL'!$A$2:$F$14,3,FALSE)) -> 1 | E8: =IF(B8="","",VLOOKUP(B8,'Transacciones CHL'!$A$2:$F$14,4,FALSE)) -> Producción / Consumo intermedio | F8: =IF(B8="","",VLOOKUP(B8,'Transacciones CHL'!$A$2:$F$14,5,FALSE)) -> 1 | G8: =IF(B8="","",VLOOKUP(B8,'Transacciones CHL'!$A$2:$F$14,6,FALSE)) -> Producción / Consumo intermedio | H8: Cría de aves de corral | I8: A | J8: Agricultura, ganadería, silvicultura y pesca | K8: Agricultura | L8: Agriculture, forestry and fishing | M8: 1 | N8: Bioeconomía | O8: 2 | P8: No culturales
A9: mp_c008 | B9: 1 | C9: =IF(B9="","",VLOOKUP(B9,'Transacciones CHL'!$A$2:$B$14,2,FALSE)) -> Producción bruta precio básico | D9: =IF(B9="","",VLOOKUP(B9,'Transacciones CHL'!$A$2:$F$14,3,FALSE)) -> 1 | E9: =IF(B9="","",VLOOKUP(B9,'Transacciones CHL'!$A$2:$F$14,4,FALSE)) -> Producción / Consumo intermedio | F9: =IF(B9="","",VLOOKUP(B9,'Transacciones CHL'!$A$2:$F$14,5,FALSE)) -> 1 | G9: =IF(B9="","",VLOOKUP(B9,'Transacciones CHL'!$A$2:$F$14,6,FALSE)) -> Producción / Consumo intermedio | H9: Cría de otros animales | I9: A | J9: Agricultura, ganadería, silvicultura y pesca | K9: Agricultura | L9: Agriculture, forestry and fishing | M9: 1 | N9: Bioeconomía | O9: 2 | P9: No culturales
A10: mp_c009 | B10: 1 | C10: =IF(B10="","",VLOOKUP(B10,'Transacciones CHL'!$A$2:$B$14,2,FALSE)) -> Producción bruta precio básico | D10: =IF(B10="","",VLOOKUP(B10,'Transacciones CHL'!$A$2:$F$14,3,FALSE)) -> 1 | E10: =IF(B10="","",VLOOKUP(B10,'Transacciones CHL'!$A$2:$F$14,4,FALSE)) -> Producción / Consumo intermedio | F10: =IF(B10="","",VLOOKUP(B10,'Transacciones CHL'!$A$2:$F$14,5,FALSE)) -> 1 | G10: =IF(B10="","",VLOOKUP(B10,'Transacciones CHL'!$A$2:$F$14,6,FALSE)) -> Producción / Consumo intermedio | H10: Actividades de apoyo a la agricultura y ganadería | I10: A | J10: Agricultura, ganadería, silvicultura y pesca | K10: Agricultura | L10: Agriculture, forestry and fishing | M10: 1 | N10: Bioeconomía | O10: 2 | P10: No culturales
A11: mp_c010 | B11: 1 | C11: =IF(B11="","",VLOOKUP(B11,'Transacciones CHL'!$A$2:$B$14,2,FALSE)) -> Producción bruta precio básico | D11: =IF(B11="","",VLOOKUP(B11,'Transacciones CHL'!$A$2:$F$14,3,FALSE)) -> 1 | E11: =IF(B11="","",VLOOKUP(B11,'Transacciones CHL'!$A$2:$F$14,4,FALSE)) -> Producción / Consumo intermedio | F11: =IF(B11="","",VLOOKUP(B11,'Transacciones CHL'!$A$2:$F$14,5,FALSE)) -> 1 | G11: =IF(B11="","",VLOOKUP(B11,'Transacciones CHL'!$A$2:$F$14,6,FALSE)) -> Producción / Consumo intermedio | H11: Silvicultura y extracción de madera | I11: A | J11: Agricultura, ganadería, silvicultura y pesca | K11: Agricultura | L11: Agriculture, forestry and fishing | M11: 1 | N11: Bioeconomía | O11: 2 | P11: No culturales
A12: mp_c011 | B12: 1 | C12: =IF(B12="","",VLOOKUP(B12,'Transacciones CHL'!$A$2:$B$14,2,FALSE)) -> Producción bruta precio básico | D12: =IF(B12="","",VLOOKUP(B12,'Transacciones CHL'!$A$2:$F$14,3,FALSE)) -> 1 | E12: =IF(B12="","",VLOOKUP(B12,'Transacciones CHL'!$A$2:$F$14,4,FALSE)) -> Producción / Consumo intermedio | F12: =IF(B12="","",VLOOKUP(B12,'Transacciones CHL'!$A$2:$F$14,5,FALSE)) -> 1 | G12: =IF(B12="","",VLOOKUP(B12,'Transacciones CHL'!$A$2:$F$14,6,FALSE)) -> Producción / Consumo intermedio | H12: Acuicultura | I12: A | J12: Agricultura, ganadería, silvicultura y pesca | K12: Agricultura | L12: Agriculture, forestry and fishing | M12: 1 | N12: Bioeconomía | O12: 2 | P12: No culturales
A13: mp_c012 | B13: 1 | C13: =IF(B13="","",VLOOKUP(B13,'Transacciones CHL'!$A$2:$B$14,2,FALSE)) -> Producción bruta precio básico | D13: =IF(B13="","",VLOOKUP(B13,'Transacciones CHL'!$A$2:$F$14,3,FALSE)) -> 1 | E13: =IF(B13="","",VLOOKUP(B13,'Transacciones CHL'!$A$2:$F$14,4,FALSE)) -> Producción / Consumo intermedio | F13: =IF(B13="","",VLOOKUP(B13,'Transacciones CHL'!$A$2:$F$14,5,FALSE)) -> 1 | G13: =IF(B13="","",VLOOKUP(B13,'Transacciones CHL'!$A$2:$F$14,6,FALSE)) -> Producción / Consumo intermedio | H13: Pesca extractiva | I13: A | J13: Agricultura, ganadería, silvicultura y pesca | K13: Agricultura | L13: Agriculture, forestry and fishing | M13: 1 | N13: Bioeconomía | O13: 2 | P13: No culturales
... A112: mp_c111 | B112: 1 | C112: =IF(B112="","",VLOOKUP(B112,'Transacciones CHL'!$A$2:$B$14,2,FALSE)) -> Producción bruta precio básico | D112: =IF(B112="","",VLOOKUP(B112,'Transacciones CHL'!$A$2:$F$14,3,FALSE)) -> 1 | E112: =IF(B112="","",VLOOKUP(B112,'Transacciones CHL'!$A$2:$F$14,4,FALSE)) -> Producción / Consumo intermedio | F112: =IF(B112="","",VLOOKUP(B112,'Transacciones CHL'!$A$2:$F$14,5,FALSE)) -> 1 | G112: =IF(B112="","",VLOOKUP(B112,'Transacciones CHL'!$A$2:$F$14,6,FALSE)) -> Producción / Consumo intermedio | H112: Otras actividades de servicios personales | I112: S | J112: Otras actividades de servicios | K112: Otros servicios | L112: Other service activities | M112: 3 | N112: No bioeconomía | O112: 2 | P112: No culturales
A113: mp_c112 | C113: =IF(B113="","",VLOOKUP(B113,'Transacciones CHL'!$A$2:$B$14,2,FALSE)) | D113: =IF(B113="","",VLOOKUP(B113,'Transacciones CHL'!$A$2:$F$14,3,FALSE)) | E113: =IF(B113="","",VLOOKUP(B113,'Transacciones CHL'!$A$2:$F$14,4,FALSE)) | F113: =IF(B113="","",VLOOKUP(B113,'Transacciones CHL'!$A$2:$F$14,5,FALSE)) | G113: =IF(B113="","",VLOOKUP(B113,'Transacciones CHL'!$A$2:$F$14,6,FALSE))
A114: ot_c001 | C114: =IF(B114="","",VLOOKUP(B114,'Transacciones CHL'!$A$2:$B$14,2,FALSE)) | D114: =IF(B114="","",VLOOKUP(B114,'Transacciones CHL'!$A$2:$F$14,3,FALSE)) | E114: =IF(B114="","",VLOOKUP(B114,'Transacciones CHL'!$A$2:$F$14,4,FALSE)) | F114: =IF(B114="","",VLOOKUP(B114,'Transacciones CHL'!$A$2:$F$14,5,FALSE)) | G114: =IF(B114="","",VLOOKUP(B114,'Transacciones CHL'!$A$2:$F$14,6,FALSE))
A115: ot_c002 | B115: 2 | C115: =IF(B115="","",VLOOKUP(B115,'Transacciones CHL'!$A$2:$B$14,2,FALSE)) -> Importaciones precios cif | D115: =IF(B115="","",VLOOKUP(B115,'Transacciones CHL'!$A$2:$F$14,3,FALSE)) -> 2 | E115: =IF(B115="","",VLOOKUP(B115,'Transacciones CHL'!$A$2:$F$14,4,FALSE)) -> Importaciones / Exportaciones | F115: =IF(B115="","",VLOOKUP(B115,'Transacciones CHL'!$A$2:$F$14,5,FALSE)) -> 2 | G115: =IF(B115="","",VLOOKUP(B115,'Transacciones CHL'!$A$2:$F$14,6,FALSE)) -> Importaciones / Exportaciones
A116: ot_c003 | C116: =IF(B116="","",VLOOKUP(B116,'Transacciones CHL'!$A$2:$B$14,2,FALSE)) | D116: =IF(B116="","",VLOOKUP(B116,'Transacciones CHL'!$A$2:$F$14,3,FALSE)) | E116: =IF(B116="","",VLOOKUP(B116,'Transacciones CHL'!$A$2:$F$14,4,FALSE)) | F116: =IF(B116="","",VLOOKUP(B116,'Transacciones CHL'!$A$2:$F$14,5,FALSE)) | G116: =IF(B116="","",VLOOKUP(B116,'Transacciones CHL'!$A$2:$F$14,6,FALSE))
A117: ot_c004 | B117: 3 | C117: =IF(B117="","",VLOOKUP(B117,'Transacciones CHL'!$A$2:$B$14,2,FALSE)) -> Impuestos indirectos sobre bienes y servicios | D117: =IF(B117="","",VLOOKUP(B117,'Transacciones CHL'!$A$2:$F$14,3,FALSE)) -> 3 | E117: =IF(B117="","",VLOOKUP(B117,'Transacciones CHL'!$A$2:$F$14,4,FALSE)) -> Impuestos indirectos sobre bienes y servicios | F117: =IF(B117="","",VLOOKUP(B117,'Transacciones CHL'!$A$2:$F$14,5,FALSE)) -> 3 | G117: =IF(B117="","",VLOOKUP(B117,'Transacciones CHL'!$A$2:$F$14,6,FALSE)) -> Impuestos
A118: ot_c005 | B118: 4 | C118: =IF(B118="","",VLOOKUP(B118,'Transacciones CHL'!$A$2:$B$14,2,FALSE)) -> Derechos de importación | D118: =IF(B118="","",VLOOKUP(B118,'Transacciones CHL'!$A$2:$F$14,3,FALSE)) -> 4 | E118: =IF(B118="","",VLOOKUP(B118,'Transacciones CHL'!$A$2:$F$14,4,FALSE)) -> Derechos de importación | F118: =IF(B118="","",VLOOKUP(B118,'Transacciones CHL'!$A$2:$F$14,5,FALSE)) -> 3 | G118: =IF(B118="","",VLOOKUP(B118,'Transacciones CHL'!$A$2:$F$14,6,FALSE)) -> Impuestos
A119: ot_c006 | C119: =IF(B119="","",VLOOKUP(B119,'Transacciones CHL'!$A$2:$B$14,2,FALSE)) | D119: =IF(B119="","",VLOOKUP(B119,'Transacciones CHL'!$A$2:$F$14,3,FALSE)) | E119: =IF(B119="","",VLOOKUP(B119,'Transacciones CHL'!$A$2:$F$14,4,FALSE)) | F119: =IF(B119="","",VLOOKUP(B119,'Transacciones CHL'!$A$2:$F$14,5,FALSE)) | G119: =IF(B119="","",VLOOKUP(B119,'Transacciones CHL'!$A$2:$F$14,6,FALSE))
A120: ot_c007 | B120: 5 | C120: =IF(B120="","",VLOOKUP(B120,'Transacciones CHL'!$A$2:$B$14,2,FALSE)) -> Margen de comercio | D120: =IF(B120="","",VLOOKUP(B120,'Transacciones CHL'!$A$2:$F$14,3,FALSE)) -> 5 | E120: =IF(B120="","",VLOOKUP(B120,'Transacciones CHL'!$A$2:$F$14,4,FALSE)) -> Margen de comercio | F120: =IF(B120="","",VLOOKUP(B120,'Transacciones CHL'!$A$2:$F$14,5,FALSE)) -> 4 | G120: =IF(B120="","",VLOOKUP(B120,'Transacciones CHL'!$A$2:$F$14,6,FALSE)) -> Márgenes
A121: ot_c008 | B121: 6 | C121: =IF(B121="","",VLOOKUP(B121,'Transacciones CHL'!$A$2:$B$14,2,FALSE)) -> Impuesto al valor agregado | D121: =IF(B121="","",VLOOKUP(B121,'Transacciones CHL'!$A$2:$F$14,3,FALSE)) -> 6 | E121: =IF(B121="","",VLOOKUP(B121,'Transacciones CHL'!$A$2:$F$14,4,FALSE)) -> Impuesto al valor agregado | F121: =IF(B121="","",VLOOKUP(B121,'Transacciones CHL'!$A$2:$F$14,5,FALSE)) -> 3 | G121: =IF(B121="","",VLOOKUP(B121,'Transacciones CHL'!$A$2:$F$14,6,FALSE)) -> Impuestos
A122: ot_c009 | C122: =IF(B122="","",VLOOKUP(B122,'Transacciones CHL'!$A$2:$B$14,2,FALSE)) | D122: =IF(B122="","",VLOOKUP(B122,'Transacciones CHL'!$A$2:$F$14,3,FALSE)) | E122: =IF(B122="","",VLOOKUP(B122,'Transacciones CHL'!$A$2:$F$14,4,FALSE)) | F122: =IF(B122="","",VLOOKUP(B122,'Transacciones CHL'!$A$2:$F$14,5,FALSE)) | G122: =IF(B122="","",VLOOKUP(B122,'Transacciones CHL'!$A$2:$F$14,6,FALSE))
A123: ui_c001 | B123: 7 | C123: =IF(B123="","",VLOOKUP(B123,'Transacciones CHL'!$A$2:$B$14,2,FALSE)) -> Consumo intermedio | D123: =IF(B123="","",VLOOKUP(B123,'Transacciones CHL'!$A$2:$F$14,3,FALSE)) -> 1 | E123: =IF(B123="","",VLOOKUP(B123,'Transacciones CHL'!$A$2:$F$14,4,FALSE)) -> Producción / Consumo intermedio | F123: =IF(B123="","",VLOOKUP(B123,'Transacciones CHL'!$A$2:$F$14,5,FALSE)) -> 1 | G123: =IF(B123="","",VLOOKUP(B123,'Transacciones CHL'!$A$2:$F$14,6,FALSE)) -> Producción / Consumo intermedio | H123: Cultivos anuales (cereales y otros) y forrajeras | I123: A | J123: Agricultura, ganadería, silvicultura y pesca | K123: Agricultura | L123: Agriculture, forestry and fishing | M123: 1 | N123: Bioeconomía | O123: 2 | P123: No culturales
A124: ui_c002 | B124: 7 | C124: =IF(B124="","",VLOOKUP(B124,'Transacciones CHL'!$A$2:$B$14,2,FALSE)) -> Consumo intermedio | D124: =IF(B124="","",VLOOKUP(B124,'Transacciones CHL'!$A$2:$F$14,3,FALSE)) -> 1 | E124: =IF(B124="","",VLOOKUP(B124,'Transacciones CHL'!$A$2:$F$14,4,FALSE)) -> Producción / Consumo intermedio | F124: =IF(B124="","",VLOOKUP(B124,'Transacciones CHL'!$A$2:$F$14,5,FALSE)) -> 1 | G124: =IF(B124="","",VLOOKUP(B124,'Transacciones CHL'!$A$2:$F$14,6,FALSE)) -> Producción / Consumo intermedio | H124: Cultivo de hortalizas y productos de viveros | I124: A | J124: Agricultura, ganadería, silvicultura y pesca | K124: Agricultura | L124: Agriculture, forestry and fishing | M124: 1 | N124: Bioeconomía | O124: 2 | P124: No culturales
A125: ui_c003 | B125: 7 | C125: =IF(B125="","",VLOOKUP(B125,'Transacciones CHL'!$A$2:$B$14,2,FALSE)) -> Consumo intermedio | D125: =IF(B125="","",VLOOKUP(B125,'Transacciones CHL'!$A$2:$F$14,3,FALSE)) -> 1 | E125: =IF(B125="","",VLOOKUP(B125,'Transacciones CHL'!$A$2:$F$14,4,FALSE)) -> Producción / Consumo intermedio | F125: =IF(B125="","",VLOOKUP(B125,'Transacciones CHL'!$A$2:$F$14,5,FALSE)) -> 1 | G125: =IF(B125="","",VLOOKUP(B125,'Transacciones CHL'!$A$2:$F$14,6,FALSE)) -> Producción / Consumo intermedio | H125: Cultivo de uva | I125: A | J125: Agricultura, ganadería, silvicultura y pesca | K125: Agricultura | L125: Agriculture, forestry and fishing | M125: 1 | N125: Bioeconomía | O125: 2 | P125: No culturales
A126: ui_c004 | B126: 7 | C126: =IF(B126="","",VLOOKUP(B126,'Transacciones CHL'!$A$2:$B$14,2,FALSE)) -> Consumo intermedio | D126: =IF(B126="","",VLOOKUP(B126,'Transacciones CHL'!$A$2:$F$14,3,FALSE)) -> 1 | E126: =IF(B126="","",VLOOKUP(B126,'Transacciones CHL'!$A$2:$F$14,4,FALSE)) -> Producción / Consumo intermedio | F126: =IF(B126="","",VLOOKUP(B126,'Transacciones CHL'!$A$2:$F$14,5,FALSE)) -> 1 | G126: =IF(B126="","",VLOOKUP(B126,'Transacciones CHL'!$A$2:$F$14,6,FALSE)) -> Producción / Consumo intermedio | H126: Cultivo de otras frutas | I126: A | J126: Agricultura, ganadería, silvicultura y pesca | K126: Agricultura | L126: Agriculture, forestry and fishing | M126: 1 | N126: Bioeconomía | O126: 2 | P126: No culturales
A127: ui_c005 | B127: 7 | C127: =IF(B127="","",VLOOKUP(B127,'Transacciones CHL'!$A$2:$B$14,2,FALSE)) -> Consumo intermedio | D127: =IF(B127="","",VLOOKUP(B127,'Transacciones CHL'!$A$2:$F$14,3,FALSE)) -> 1 | E127: =IF(B127="","",VLOOKUP(B127,'Transacciones CHL'!$A$2:$F$14,4,FALSE)) -> Producción / Consumo intermedio | F127: =IF(B127="","",VLOOKUP(B127,'Transacciones CHL'!$A$2:$F$14,5,FALSE)) -> 1 | G127: =IF(B127="","",VLOOKUP(B127,'Transacciones CHL'!$A$2:$F$14,6,FALSE)) -> Producción / Consumo intermedio | H127: Cría de ganado bovino | I127: A | J127: Agricultura, ganadería, silvicultura y pesca | K127: Agricultura | L127: Agriculture, forestry and fishing | M127: 1 | N127: Bioeconomía | O127: 2 | P127: No culturales
A128: ui_c006 | B128: 7 | C128: =IF(B128="","",VLOOKUP(B128,'Transacciones CHL'!$A$2:$B$14,2,FALSE)) -> Consumo intermedio | D128: =IF(B128="","",VLOOKUP(B128,'Transacciones CHL'!$A$2:$F$14,3,FALSE)) -> 1 | E128: =IF(B128="","",VLOOKUP(B128,'Transacciones CHL'!$A$2:$F$14,4,FALSE)) -> Producción / Consumo intermedio | F128: =IF(B128="","",VLOOKUP(B128,'Transacciones CHL'!$A$2:$F$14,5,FALSE)) -> 1 | G128: =IF(B128="","",VLOOKUP(B128,'Transacciones CHL'!$A$2:$F$14,6,FALSE)) -> Producción / Consumo intermedio | H128: Cría de cerdos | I128: A | J128: Agricultura, ganadería, silvicultura y pesca | K128: Agricultura | L128: Agriculture, forestry and fishing | M128: 1 | N128: Bioeconomía | O128: 2 | P128: No culturales
A129: ui_c007 | B129: 7 | C129: =IF(B129="","",VLOOKUP(B129,'Transacciones CHL'!$A$2:$B$14,2,FALSE)) -> Consumo intermedio | D129: =IF(B129="","",VLOOKUP(B129,'Transacciones CHL'!$A$2:$F$14,3,FALSE)) -> 1 | E129: =IF(B129="","",VLOOKUP(B129,'Transacciones CHL'!$A$2:$F$14,4,FALSE)) -> Producción / Consumo intermedio | F129: =IF(B129="","",VLOOKUP(B129,'Transacciones CHL'!$A$2:$F$14,5,FALSE)) -> 1 | G129: =IF(B129="","",VLOOKUP(B129,'Transacciones CHL'!$A$2:$F$14,6,FALSE)) -> Producción / Consumo intermedio | H129: Cría de aves de corral | I129: A | J129: Agricultura, ganadería, silvicultura y pesca | K129: Agricultura | L129: Agriculture, forestry and fishing | M129: 1 | N129: Bioeconomía | O129: 2 | P129: No culturales
A130: ui_c008 | B130: 7 | C130: =IF(B130="","",VLOOKUP(B130,'Transacciones CHL'!$A$2:$B$14,2,FALSE)) -> Consumo intermedio | D130: =IF(B130="","",VLOOKUP(B130,'Transacciones CHL'!$A$2:$F$14,3,FALSE)) -> 1 | E130: =IF(B130="","",VLOOKUP(B130,'Transacciones CHL'!$A$2:$F$14,4,FALSE)) -> Producción / Consumo intermedio | F130: =IF(B130="","",VLOOKUP(B130,'Transacciones CHL'!$A$2:$F$14,5,FALSE)) -> 1 | G130: =IF(B130="","",VLOOKUP(B130,'Transacciones CHL'!$A$2:$F$14,6,FALSE)) -> Producción / Consumo intermedio | H130: Cría de otros animales | I130: A | J130: Agricultura, ganadería, silvicultura y pesca | K130: Agricultura | L130: Agriculture, forestry and fishing | M130: 1 | N130: Bioeconomía | O130: 2 | P130: No culturales
A131: ui_c009 | B131: 7 | C131: =IF(B131="","",VLOOKUP(B131,'Transacciones CHL'!$A$2:$B$14,2,FALSE)) -> Consumo intermedio | D131: =IF(B131="","",VLOOKUP(B131,'Transacciones CHL'!$A$2:$F$14,3,FALSE)) -> 1 | E131: =IF(B131="","",VLOOKUP(B131,'Transacciones CHL'!$A$2:$F$14,4,FALSE)) -> Producción / Consumo intermedio | F131: =IF(B131="","",VLOOKUP(B131,'Transacciones CHL'!$A$2:$F$14,5,FALSE)) -> 1 | G131: =IF(B131="","",VLOOKUP(B131,'Transacciones CHL'!$A$2:$F$14,6,FALSE)) -> Producción / Consumo intermedio | H131: Actividades de apoyo a la agricultura y ganadería | I131: A | J131: Agricultura, ganadería, silvicultura y pesca | K131: Agricultura | L131: Agriculture, forestry and fishing | M131: 1 | N131: Bioeconomía | O131: 2 | P131: No culturales
A132: ui_c010 | B132: 7 | C132: =IF(B132="","",VLOOKUP(B132,'Transacciones CHL'!$A$2:$B$14,2,FALSE)) -> Consumo intermedio | D132: =IF(B132="","",VLOOKUP(B132,'Transacciones CHL'!$A$2:$F$14,3,FALSE)) -> 1 | E132: =IF(B132="","",VLOOKUP(B132,'Transacciones CHL'!$A$2:$F$14,4,FALSE)) -> Producción / Consumo intermedio | F132: =IF(B132="","",VLOOKUP(B132,'Transacciones CHL'!$A$2:$F$14,5,FALSE)) -> 1 | G132: =IF(B132="","",VLOOKUP(B132,'Transacciones CHL'!$A$2:$F$14,6,FALSE)) -> Producción / Consumo intermedio | H132: Silvicultura y extracción de madera | I132: A | J132: Agricultura, ganadería, silvicultura y pesca | K132: Agricultura | L132: Agriculture, forestry and fishing | M132: 1 | N132: Bioeconomía | O132: 2 | P132: No culturales
A133: ui_c011 | B133: 7 | C133: =IF(B133="","",VLOOKUP(B133,'Transacciones CHL'!$A$2:$B$14,2,FALSE)) -> Consumo intermedio | D133: =IF(B133="","",VLOOKUP(B133,'Transacciones CHL'!$A$2:$F$14,3,FALSE)) -> 1 | E133: =IF(B133="","",VLOOKUP(B133,'Transacciones CHL'!$A$2:$F$14,4,FALSE)) -> Producción / Consumo intermedio | F133: =IF(B133="","",VLOOKUP(B133,'Transacciones CHL'!$A$2:$F$14,5,FALSE)) -> 1 | G133: =IF(B133="","",VLOOKUP(B133,'Transacciones CHL'!$A$2:$F$14,6,FALSE)) -> Producción / Consumo intermedio | H133: Acuicultura | I133: A | J133: Agricultura, ganadería, silvicultura y pesca | K133: Agricultura | L133: Agriculture, forestry and fishing | M133: 1 | N133: Bioeconomía | O133: 2 | P133: No culturales
A134: ui_c012 | B134: 7 | C134: =IF(B134="","",VLOOKUP(B134,'Transacciones CHL'!$A$2:$B$14,2,FALSE)) -> Consumo intermedio | D134: =IF(B134="","",VLOOKUP(B134,'Transacciones CHL'!$A$2:$F$14,3,FALSE)) -> 1 | E134: =IF(B134="","",VLOOKUP(B134,'Transacciones CHL'!$A$2:$F$14,4,FALSE)) -> Producción / Consumo intermedio | F134: =IF(B134="","",VLOOKUP(B134,'Transacciones CHL'!$A$2:$F$14,5,FALSE)) -> 1 | G134: =IF(B134="","",VLOOKUP(B134,'Transacciones CHL'!$A$2:$F$14,6,FALSE)) -> Producción / Consumo intermedio | H134: Pesca extractiva | I134: A | J134: Agricultura, ganadería, silvicultura y pesca | K134: Agricultura | L134: Agriculture, forestry and fishing | M134: 1 | N134: Bioeconomía | O134: 2 | P134: No culturales
... A233: ui_c111 | B233: 7 | C233: =IF(B233="","",VLOOKUP(B233,'Transacciones CHL'!$A$2:$B$14,2,FALSE)) -> Consumo intermedio | D233: =IF(B233="","",VLOOKUP(B233,'Transacciones CHL'!$A$2:$F$14,3,FALSE)) -> 1 | E233: =IF(B233="","",VLOOKUP(B233,'Transacciones CHL'!$A$2:$F$14,4,FALSE)) -> Producción / Consumo intermedio | F233: =IF(B233="","",VLOOKUP(B233,'Transacciones CHL'!$A$2:$F$14,5,FALSE)) -> 1 | G233: =IF(B233="","",VLOOKUP(B233,'Transacciones CHL'!$A$2:$F$14,6,FALSE)) -> Producción / Consumo intermedio | H233: Otras actividades de servicios personales | I233: S | J233: Otras actividades de servicios | K233: Otros servicios | L233: Other service activities | M233: 3 | N233: No bioeconomía | O233: 2 | P233: No culturales
A234: ui_c112 | C234: =IF(B234="","",VLOOKUP(B234,'Transacciones CHL'!$A$2:$B$14,2,FALSE)) | D234: =IF(B234="","",VLOOKUP(B234,'Transacciones CHL'!$A$2:$F$14,3,FALSE)) | E234: =IF(B234="","",VLOOKUP(B234,'Transacciones CHL'!$A$2:$F$14,4,FALSE)) | F234: =IF(B234="","",VLOOKUP(B234,'Transacciones CHL'!$A$2:$F$14,5,FALSE)) | G234: =IF(B234="","",VLOOKUP(B234,'Transacciones CHL'!$A$2:$F$14,6,FALSE))
A235: ut_c001 | C235: =IF(B235="","",VLOOKUP(B235,'Transacciones CHL'!$A$2:$B$14,2,FALSE)) | D235: =IF(B235="","",VLOOKUP(B235,'Transacciones CHL'!$A$2:$F$14,3,FALSE)) | E235: =IF(B235="","",VLOOKUP(B235,'Transacciones CHL'!$A$2:$F$14,4,FALSE)) | F235: =IF(B235="","",VLOOKUP(B235,'Transacciones CHL'!$A$2:$F$14,5,FALSE)) | G235: =IF(B235="","",VLOOKUP(B235,'Transacciones CHL'!$A$2:$F$14,6,FALSE))
A236: ut_c002 | B236: 8 | C236: =IF(B236="","",VLOOKUP(B236,'Transacciones CHL'!$A$2:$B$14,2,FALSE)) -> Consumo de hogares | D236: =IF(B236="","",VLOOKUP(B236,'Transacciones CHL'!$A$2:$F$14,3,FALSE)) -> 7 | E236: =IF(B236="","",VLOOKUP(B236,'Transacciones CHL'!$A$2:$F$14,4,FALSE)) -> Consumo de hogares | F236: =IF(B236="","",VLOOKUP(B236,'Transacciones CHL'!$A$2:$F$14,5,FALSE)) -> 5 | G236: =IF(B236="","",VLOOKUP(B236,'Transacciones CHL'!$A$2:$F$14,6,FALSE)) -> Consumo final
...

Sheet FilasC
A1: Filas | B1: Áreas Transaccionales Filas No. | C1: Áreas Transaccionales Filas Descripción | D1: Codigo Transacción Filas | E1: Transacción filas | F1: Código Productos (CUP) | G1: Productos (CUP) | H1: Código Bioeconomía Productos | I1: Bioeconomía Productos | J1: Código CUPc | K1: CUPc
A2: mp_f001 | B2: ATF01 | C2: Producción | D2: P1 | E2: Producción | F2: 1 | G2: Trigo | H2: 1 | I2: Bioeconomía | J2: 2 | K2: No culturales
A3: mp_f002 | B3: ATF01 | C3: Producción | D3: P1 | E3: Producción | F3: 2 | G3: Maíz | H3: 1 | I3: Bioeconomía | J3: 2 | K3: No culturales
A4: mp_f003 | B4: ATF01 | C4: Producción | D4: P1 | E4: Producción | F4: 3 | G4: Otros cereales | H4: 1 | I4: Bioeconomía | J4: 2 | K4: No culturales
A5: mp_f004 | B5: ATF01 | C5: Producción | D5: P1 | E5: Producción | F5: 4 | G5: Tubérculos y legumbres | H5: 1 | I5: Bioeconomía | J5: 2 | K5: No culturales
A6: mp_f005 | B6: ATF01 | C6: Producción | D6: P1 | E6: Producción | F6: 5 | G6: Forrajeras y otros cultivos de uso industrial | H6: 1 | I6: Bioeconomía | J6: 2 | K6: No culturales
A7: mp_f006 | B7: ATF01 | C7: Producción | D7: P1 | E7: Producción | F7: 6 | G7: Hortalizas y setas | H7: 1 | I7: Bioeconomía | J7: 2 | K7: No culturales
A8: mp_f007 | B8: ATF01 | C8: Producción | D8: P1 | E8: Producción | F8: 7 | G8: Uva vinífera y pisquera | H8: 1 | I8: Bioeconomía | J8: 2 | K8: No culturales
A9: mp_f008 | B9: ATF01 | C9: Producción | D9: P1 | E9: Producción | F9: 8 | G9: Uva de mesa | H9: 1 | I9: Bioeconomía | J9: 2 | K9: No culturales
A10: mp_f009 | B10: ATF01 | C10: Producción | D10: P1 | E10: Producción | F10: 9 | G10: Manzanas | H10: 1 | I10: Bioeconomía | J10: 2 | K10: No culturales
A11: mp_f010 | B11: ATF01 | C11: Producción | D11: P1 | E11: Producción | F11: 10 | G11: Duraznos y otros carozos | H11: 1 | I11: Bioeconomía | J11: 2 | K11: No culturales
A12: mp_f011 | B12: ATF01 | C12: Producción | D12: P1 | E12: Producción | F12: 11 | G12: Paltas | H12: 1 | I12: Bioeconomía | J12: 2 | K12: No culturales
A13: mp_f012 | B13: ATF01 | C13: Producción | D13: P1 | E13: Producción | F13: 12 | G13: Kiwis y otras frutas tropicales | H13: 1 | I13: Bioeconomía | J13: 2 | K13: No culturales
... A725: ut_f181 | B725: ATF02 | C725: Consumo intermedio | D725: P2 | E725: Consumo intermedio | F725: 181 | G725: Otros bienes y servicios | H725: 3 | I725: No bioeconomía | J725: 2 | K725: No culturales
A726: va_f001 | B726: ATF06 | C726: Valor Agregado | D726: P91 | E726: Remuneraciones
A727: va_f002
A728: va_f003
A729: va_f004 | B729: ATF06 | C729: Valor Agregado | D729: P92 | E729: Excedente bruto de explotación
A730: va_f005
A731: va_f006
A732: va_f007 | B732: ATF06 | C732: Valor Agregado | D732: P93 | E732: Impuestos netos sobre los productos
A733: va_f008
A734: va_f009
A735: va_f010 | B735: ATF06 | C735: Valor Agregado | D735: P94 | E735: Otros impuestos netos sobre la producción

Sheet ColumnasC
A1: Columnas | B1: Código Transacciones | C1: Código área transaccional | D1: Área transaccional | E1: Transacciones | F1: Correlativo Transacciones Agregadas | G1: Código Transacciones Agregadas | H1: Transacciones Agregadas | I1: Código Subtransacción | J1: Subtransacción | K1: Código Actividades (CAE) | L1: Actividades (CAE) | M1: CIIU Secciones | N1: CIIU Secciones descripción | O1: CIIU Corto | P1: CIIU English | Q1: Correlativo Bioeconomía Actividades | R1: Bioeconomía Actividades | S1: Código CAEc | T1: CAEc
A2: mp_c001 | B2: P10 | C2: ATC01 | D2: Producción / Consumo intermedio | E2: Producción | F2: 1 | G2: P1 | H2: Producción | I2: 1 | J2: Producción | K2: 1 | L2: Cultivos anuales (cereales y otros) y forrajeras | M2: A | N2: Agricultura, ganadería, silvicultura y pesca | O2: Agricultura | P2: Agriculture, forestry and fishing | Q2: 1 | R2: Bioeconomía | S2: 2 | T2: No culturales
A3: mp_c002 | B3: P10 | C3: ATC01 | D3: Producción / Consumo intermedio | E3: Producción | F3: 1 | G3: P1 | H3: Producción | I3: 1 | J3: Producción | K3: 2 | L3: Cultivo de hortalizas y productos de viveros | M3: A | N3: Agricultura, ganadería, silvicultura y pesca | O3: Agricultura | P3: Agriculture, forestry and fishing | Q3: 1 | R3: Bioeconomía | S3: 2 | T3: No culturales
A4: mp_c003 | B4: P10 | C4: ATC01 | D4: Producción / Consumo intermedio | E4: Producción | F4: 1 | G4: P1 | H4: Producción | I4: 1 | J4: Producción | K4: 3 | L4: Cultivo de uva | M4: A | N4: Agricultura, ganadería, silvicultura y pesca | O4: Agricultura | P4: Agriculture, forestry and fishing | Q4: 1 | R4: Bioeconomía | S4: 2 | T4: No culturales
A5: mp_c004 | B5: P10 | C5: ATC01 | D5: Producción / Consumo intermedio | E5: Producción | F5: 1 | G5: P1 | H5: Producción | I5: 1 | J5: Producción | K5: 4 | L5: Cultivo de otras frutas | M5: A | N5: Agricultura, ganadería, silvicultura y pesca | O5: Agricultura | P5: Agriculture, forestry and fishing | Q5: 1 | R5: Bioeconomía | S5: 2 | T5: No culturales
A6: mp_c005 | B6: P10 | C6: ATC01 | D6: Producción / Consumo intermedio | E6: Producción | F6: 1 | G6: P1 | H6: Producción | I6: 1 | J6: Producción | K6: 5 | L6: Cría de ganado bovino | M6: A | N6: Agricultura, ganadería, silvicultura y pesca | O6: Agricultura | P6: Agriculture, forestry and fishing | Q6: 1 | R6: Bioeconomía | S6: 2 | T6: No culturales
A7: mp_c006 | B7: P10 | C7: ATC01 | D7: Producción / Consumo intermedio | E7: Producción | F7: 1 | G7: P1 | H7: Producción | I7: 1 | J7: Producción | K7: 6 | L7: Cría de cerdos | M7: A | N7: Agricultura, ganadería, silvicultura y pesca | O7: Agricultura | P7: Agriculture, forestry and fishing | Q7: 1 | R7: Bioeconomía | S7: 2 | T7: No culturales
A8: mp_c007 | B8: P10 | C8: ATC01 | D8: Producción / Consumo intermedio | E8: Producción | F8: 1 | G8: P1 | H8: Producción | I8: 1 | J8: Producción | K8: 7 | L8: Cría de aves de corral | M8: A | N8: Agricultura, ganadería, silvicultura y pesca | O8: Agricultura | P8: Agriculture, forestry and fishing | Q8: 1 | R8: Bioeconomía | S8: 2 | T8: No culturales
A9: mp_c008 | B9: P10 | C9: ATC01 | D9: Producción / Consumo intermedio | E9: Producción | F9: 1 | G9: P1 | H9: Producción | I9: 1 | J9: Producción | K9: 8 | L9: Cría de otros animales | M9: A | N9: Agricultura, ganadería, silvicultura y pesca | O9: Agricultura | P9: Agriculture, forestry and fishing | Q9: 1 | R9: Bioeconomía | S9: 2 | T9: No culturales
A10: mp_c009 | B10: P10 | C10: ATC01 | D10: Producción / Consumo intermedio | E10: Producción | F10: 1 | G10: P1 | H10: Producción | I10: 1 | J10: Producción | K10: 9 | L10: Actividades de apoyo a la agricultura y ganadería | M10: A | N10: Agricultura, ganadería, silvicultura y pesca | O10: Agricultura | P10: Agriculture, forestry and fishing | Q10: 1 | R10: Bioeconomía | S10: 2 | T10: No culturales
A11: mp_c010 | B11: P10 | C11: ATC01 | D11: Producción / Consumo intermedio | E11: Producción | F11: 1 | G11: P1 | H11: Producción | I11: 1 | J11: Producción | K11: 10 | L11: Silvicultura y extracción de madera | M11: A | N11: Agricultura, ganadería, silvicultura y pesca | O11: Agricultura | P11: Agriculture, forestry and fishing | Q11: 1 | R11: Bioeconomía | S11: 2 | T11: No culturales
A12: mp_c011 | B12: P10 | C12: ATC01 | D12: Producción / Consumo intermedio | E12: Producción | F12: 1 | G12: P1 | H12: Producción | I12: 1 | J12: Producción | K12: 11 | L12: Acuicultura | M12: A | N12: Agricultura, ganadería, silvicultura y pesca | O12: Agricultura | P12: Agriculture, forestry and fishing | Q12: 1 | R12: Bioeconomía | S12: 2 | T12: No culturales
A13: mp_c012 | B13: P10 | C13: ATC01 | D13: Producción / Consumo intermedio | E13: Producción | F13: 1 | G13: P1 | H13: Producción | I13: 1 | J13: Producción | K13: 12 | L13: Pesca extractiva | M13: A | N13: Agricultura, ganadería, silvicultura y pesca | O13: Agricultura | P13: Agriculture, forestry and fishing | Q13: 1 | R13: Bioeconomía | S13: 2 | T13: No culturales
... A112: mp_c111 | B112: P10 | C112: ATC01 | D112: Producción / Consumo intermedio | E112: Producción | F112: 1 | G112: P1 | H112: Producción | I112: 1 | J112: Producción | K112: 111 | L112: Otras actividades de servicios personales | M112: S | N112: Otras actividades de servicios | O112: Otros servicios | P112: Other service activities | Q112: 3 | R112: No bioeconomía | S112: 2 | T112: No culturales
A113: mp_c112
A114: ot_c001
A115: ot_c002 | B115: P70 | C115: ATC02 | D115: Exportaciones / Importaciones | E115: Importaciones de bienes Y SERVICIOS | F115: 7 | G115: P7 | H115: Importaciones de bienes y servicios | I115: 2 | J115: Importaciones precios cif
A116: ot_c003
A117: ot_c004 | B117: D214 | C117: ATC04 | D117: Impuestos menos subvenciones sobre los productos | E117: Impuestos sobre los productos, excepto IVA e impuestos sobre las importaciones | F117: 9 | G117: D2 | H117: Impuestos sobre la producción y las importaciones | I117: 3 | J117: Impuestos indirectos sobre bienes y servicios
A118: ot_c005 | B118: D212 | C118: ATC04 | D118: Impuestos menos subvenciones sobre los productos | E118: Impuestos y derechos sobre las importaciones excepto IVA | F118: 9 | G118: D2 | H118: Impuestos sobre la producción y las importaciones | I118: 4 | J118: Derechos de importación
A119: ot_c006
A120: ot_c007 | B120: M11 | C120: ATC05 | D120: Márgenes de distribución | E120: Márgenes de comercio | F120: 12 | G120: M1 | H120: Márgenes de distribución | I120: 5 | J120: Margen de comercio
A121: ot_c008 | B121: D211 | C121: ATC04 | D121: Impuestos menos subvenciones sobre los productos | E121: Impuestos tipo valor agregado (IVA) | F121: 9 | G121: D2 | H121: Impuestos sobre la producción y las importaciones | I121: 6 | J121: Impuesto al valor agregado
A122: ot_c009
A123: ui_c001 | B123: P20 | C123: ATC01 | D123: Producción / Consumo intermedio | E123: Consumo | F123: 2 | G123: P2 | H123: Consumo intermedio | I123: 1 | J123: Producción | K123: 1 | L123: Cultivos anuales (cereales y otros) y forrajeras | M123: A | N123: Agricultura, ganadería, silvicultura y pesca | O123: Agricultura | P123: Agriculture, forestry and fishing | Q123: 1 | R123: Bioeconomía | S123: 2 | T123: No culturales
A124: ui_c002 | B124: P20 | C124: ATC01 | D124: Producción / Consumo intermedio | E124: Consumo | F124: 2 | G124: P2 | H124: Consumo intermedio | I124: 1 | J124: Producción | K124: 2 | L124: Cultivo de hortalizas y productos de viveros | M124: A | N124: Agricultura, ganadería, silvicultura y pesca | O124: Agricultura | P124: Agriculture, forestry and fishing | Q124: 1 | R124: Bioeconomía | S124: 2 | T124: No culturales
A125: ui_c003 | B125: P20 | C125: ATC01 | D125: Producción / Consumo intermedio | E125: Consumo | F125: 2 | G125: P2 | H125: Consumo intermedio | I125: 1 | J125: Producción | K125: 3 | L125: Cultivo de uva | M125: A | N125: Agricultura, ganadería, silvicultura y pesca | O125: Agricultura | P125: Agriculture, forestry and fishing | Q125: 1 | R125: Bioeconomía | S125: 2 | T125: No culturales
A126: ui_c004 | B126: P20 | C126: ATC01 | D126: Producción / Consumo intermedio | E126: Consumo | F126: 2 | G126: P2 | H126: Consumo intermedio | I126: 1 | J126: Producción | K126: 4 | L126: Cultivo de otras frutas | M126: A | N126: Agricultura, ganadería, silvicultura y pesca | O126: Agricultura | P126: Agriculture, forestry and fishing | Q126: 1 | R126: Bioeconomía | S126: 2 | T126: No culturales
A127: ui_c005 | B127: P20 | C127: ATC01 | D127: Producción / Consumo intermedio | E127: Consumo | F127: 2 | G127: P2 | H127: Consumo intermedio | I127: 1 | J127: Producción | K127: 5 | L127: Cría de ganado bovino | M127: A | N127: Agricultura, ganadería, silvicultura y pesca | O127: Agricultura | P127: Agriculture, forestry and fishing | Q127: 1 | R127: Bioeconomía | S127: 2 | T127: No culturales
A128: ui_c006 | B128: P20 | C128: ATC01 | D128: Producción / Consumo intermedio | E128: Consumo | F128: 2 | G128: P2 | H128: Consumo intermedio | I128: 1 | J128: Producción | K128: 6 | L128: Cría de cerdos | M128: A | N128: Agricultura, ganadería, silvicultura y pesca | O128: Agricultura | P128: Agriculture, forestry and fishing | Q128: 1 | R128: Bioeconomía | S128: 2 | T128: No culturales
A129: ui_c007 | B129: P20 | C129: ATC01 | D129: Producción / Consumo intermedio | E129: Consumo | F129: 2 | G129: P2 | H129: Consumo intermedio | I129: 1 | J129: Producción | K129: 7 | L129: Cría de aves de corral | M129: A | N129: Agricultura, ganadería, silvicultura y pesca | O129: Agricultura | P129: Agriculture, forestry and fishing | Q129: 1 | R129: Bioeconomía | S129: 2 | T129: No culturales
A130: ui_c008 | B130: P20 | C130: ATC01 | D130: Producción / Consumo intermedio | E130: Consumo | F130: 2 | G130: P2 | H130: Consumo intermedio | I130: 1 | J130: Producción | K130: 8 | L130: Cría de otros animales | M130: A | N130: Agricultura, ganadería, silvicultura y pesca | O130: Agricultura | P130: Agriculture, forestry and fishing | Q130: 1 | R130: Bioeconomía | S130: 2 | T130: No culturales
A131: ui_c009 | B131: P20 | C131: ATC01 | D131: Producción / Consumo intermedio | E131: Consumo | F131: 2 | G131: P2 | H131: Consumo intermedio | I131: 1 | J131: Producción | K131: 9 | L131: Actividades de apoyo a la agricultura y ganadería | M131: A | N131: Agricultura, ganadería, silvicultura y pesca | O131: Agricultura | P131: Agriculture, forestry and fishing | Q131: 1 | R131: Bioeconomía | S131: 2 | T131: No culturales
A132: ui_c010 | B132: P20 | C132: ATC01 | D132: Producción / Consumo intermedio | E132: Consumo | F132: 2 | G132: P2 | H132: Consumo intermedio | I132: 1 | J132: Producción | K132: 10 | L132: Silvicultura y extracción de madera | M132: A | N132: Agricultura, ganadería, silvicultura y pesca | O132: Agricultura | P132: Agriculture, forestry and fishing | Q132: 1 | R132: Bioeconomía | S132: 2 | T132: No culturales
A133: ui_c011 | B133: P20 | C133: ATC01 | D133: Producción / Consumo intermedio | E133: Consumo | F133: 2 | G133: P2 | H133: Consumo intermedio | I133: 1 | J133: Producción | K133: 11 | L133: Acuicultura | M133: A | N133: Agricultura, ganadería, silvicultura y pesca | O133: Agricultura | P133: Agriculture, forestry and fishing | Q133: 1 | R133: Bioeconomía | S133: 2 | T133: No culturales
A134: ui_c012 | B134: P20 | C134: ATC01 | D134: Producción / Consumo intermedio | E134: Consumo | F134: 2 | G134: P2 | H134: Consumo intermedio | I134: 1 | J134: Producción | K134: 12 | L134: Pesca extractiva | M134: A | N134: Agricultura, ganadería, silvicultura y pesca | O134: Agricultura | P134: Agriculture, forestry and fishing | Q134: 1 | R134: Bioeconomía | S134: 2 | T134: No culturales
... A233: ui_c111 | B233: P20 | C233: ATC01 | D233: Producción / Consumo intermedio | E233: Consumo | F233: 2 | G233: P2 | H233: Consumo intermedio | I233: 1 | J233: Producción | K233: 111 | L233: Otras actividades de servicios personales | M233: S | N233: Otras actividades de servicios | O233: Otros servicios | P233: Other service activities | Q233: 3 | R233: No bioeconomía | S233: 2 | T233: No culturales
A234: ui_c112
A235: ut_c001
A236: ut_c002 | B236: Pa31 | C236: ATC06 | D236: Gasto de consumo final | E236: Gasto de consumo final de los hogares | F236: 3 | G236: P3 | H236: Gasto de consumo final | I236: 7 | J236: Consumo de hogares
...

Sheet Actividades
A1: Código Actividades (CAE) | B1: Actividades (CAE) | C1: Código Secciones CIIU | D1: Secciones CIIU | E1: Nombre Corto Secciones CIIU | F1: ISIC Sections (CIIU Inglés) | G1: Código Bioeconomía Actividades | H1: Bioeconomía Actividades | I1: Código CAEc | J1: CAEc
A2: 1 | B2: Cultivos anuales (cereales y otros) y forrajeras | C2: A | D2: Agricultura, ganadería, silvicultura y pesca | E2: Agricultura | F2: Agriculture, forestry and fishing | G2: 1 | H2: Bioeconomía | I2: 2 | J2: No culturales
A3: 2 | B3: Cultivo de hortalizas y productos de viveros | C3: A | D3: Agricultura, ganadería, silvicultura y pesca | E3: Agricultura | F3: Agriculture, forestry and fishing | G3: 1 | H3: Bioeconomía | I3: 2 | J3: No culturales
A4: 3 | B4: Cultivo de uva | C4: A | D4: Agricultura, ganadería, silvicultura y pesca | E4: Agricultura | F4: Agriculture, forestry and fishing | G4: 1 | H4: Bioeconomía | I4: 2 | J4: No culturales
A5: 4 | B5: Cultivo de otras frutas | C5: A | D5: Agricultura, ganadería, silvicultura y pesca | E5: Agricultura | F5: Agriculture, forestry and fishing | G5: 1 | H5: Bioeconomía | I5: 2 | J5: No culturales
A6: 5 | B6: Cría de ganado bovino | C6: A | D6: Agricultura, ganadería, silvicultura y pesca | E6: Agricultura | F6: Agriculture, forestry and fishing | G6: 1 | H6: Bioeconomía | I6: 2 | J6: No culturales
A7: 6 | B7: Cría de cerdos | C7: A | D7: Agricultura, ganadería, silvicultura y pesca | E7: Agricultura | F7: Agriculture, forestry and fishing | G7: 1 | H7: Bioeconomía | I7: 2 | J7: No culturales
A8: 7 | B8: Cría de aves de corral | C8: A | D8: Agricultura, ganadería, silvicultura y pesca | E8: Agricultura | F8: Agriculture, forestry and fishing | G8: 1 | H8: Bioeconomía | I8: 2 | J8: No culturales
A9: 8 | B9: Cría de otros animales | C9: A | D9: Agricultura, ganadería, silvicultura y pesca | E9: Agricultura | F9: Agriculture, forestry and fishing | G9: 1 | H9: Bioeconomía | I9: 2 | J9: No culturales
A10: 9 | B10: Actividades de apoyo a la agricultura y ganadería | C10: A | D10: Agricultura, ganadería, silvicultura y pesca | E10: Agricultura | F10: Agriculture, forestry and fishing | G10: 1 | H10: Bioeconomía | I10: 2 | J10: No culturales
A11: 10 | B11: Silvicultura y extracción de madera | C11: A | D11: Agricultura, ganadería, silvicultura y pesca | E11: Agricultura | F11: Agriculture, forestry and fishing | G11: 1 | H11: Bioeconomía | I11: 2 | J11: No culturales
A12: 11 | B12: Acuicultura | C12: A | D12: Agricultura, ganadería, silvicultura y pesca | E12: Agricultura | F12: Agriculture, forestry and fishing | G12: 1 | H12: Bioeconomía | I12: 2 | J12: No culturales
A13: 12 | B13: Pesca extractiva | C13: A | D13: Agricultura, ganadería, silvicultura y pesca | E13: Agricultura | F13: Agriculture, forestry and fishing | G13: 1 | H13: Bioeconomía | I13: 2 | J13: No culturales
... A112: 111 | B112: Otras actividades de servicios personales | C112: S | D112: Otras actividades de servicios | E112: Otros servicios | F112: Other service activities | G112: 3 | H112: No bioeconomía | I112: 2 | J112: No culturales
A113: 112 | B113: Actividades no especificada

Sheet Transacciones CHL
A1: Código Transacciones | B1: Transacciones | C1: Código Áreas Transaccionales | D1: Áreas Transaccionales | E1: Código ATC | F1: ATC
A2: 1 | B2: Producción bruta precio básico | C2: 1 | D2: Producción / Consumo intermedio | E2: 1 | F2: Producción / Consumo intermedio
A3: 2 | B3: Importaciones precios cif | C3: 2 | D3: Importaciones / Exportaciones | E3: 2 | F3: Importaciones / Exportaciones
A4: 3 | B4: Impuestos indirectos sobre bienes y servicios | C4: 3 | D4: Impuestos indirectos sobre bienes y servicios | E4: 3 | F4: Impuestos
A5: 4 | B5: Derechos de importación | C5: 4 | D5: Derechos de importación | E5: 3 | F5: Impuestos
A6: 5 | B6: Margen de comercio | C6: 5 | D6: Margen de comercio | E6: 4 | F6: Márgenes
A7: 6 | B7: Impuesto al valor agregado | C7: 6 | D7: Impuesto al valor agregado | E7: 3 | F7: Impuestos
A8: 7 | B8: Consumo intermedio | C8: 1 | D8: Producción / Consumo intermedio | E8: 1 | F8: Producción / Consumo intermedio
A9: 8 | B9: Consumo de hogares | C9: 7 | D9: Consumo de hogares | E9: 5 | F9: Consumo final
A10: 9 | B10: Consumo de IPSFL | C10: 8 | D10: Consumo de IPSFL | E10: 5 | F10: Consumo final
A11: 10 | B11: Consumo de gobierno | C11: 9 | D11: Consumo de gobierno | E11: 5 | F11: Consumo final
A12: 11 | B12: Formación bruta de capital fijo | C12: 10 | D12: Formación bruta de capital fijo | E12: 6 | F12: FBK / Variación existencias
A13: 12 | B13: Variación de existencias | C13: 11 | D13: Variación de existencias | E13: 6 | F13: FBK / Variación existencias
A14: 13 | B14: Exportaciones | C14: 2 | D14: Importaciones / Exportaciones | E14: 2 | F14: Importaciones / Exportaciones

Sheet Transacciones 
A1: Código Transacciones | B1: Código área transaccional | C1: Área transaccional | D1: Transacciones | E1: Correlativo Transacciones Agregadas | F1: Código Transacciones Agregadas | G1: Transacciones Agregadas | H1: corr_ntg2 | I1: id_area_columnas
A2: P10 | B2: ATC01 | C2: Producción / Consumo intermedio | D2: Producción | E2: 1 | F2: P1 | G2: Producción | H2: 1 | I2: 0
A3: P11 | B3: ATC01 | C3: Producción / Consumo intermedio | D3: Producción de mercado | E3: 1 | F3: P1 | G3: Producción | H3: 2 | I3: 1
A4: P12 | B4: ATC01 | C4: Producción / Consumo intermedio | D4: Producción para uso final propio | E4: 1 | F4: P1 | G4: Producción | H4: 3 | I4: 2
A5: P13 | B5: ATC01 | C5: Producción / Consumo intermedio | D5: Otra producción no de mercado | E5: 1 | F5: P1 | G5: Producción | H5: 4 | I5: 3
A6: P20 | B6: ATC01 | C6: Producción / Consumo intermedio | D6: Consumo | E6: 2 | F6: P2 | G6: Consumo intermedio | H6: 5 | I6: 0
A7: P21 | B7: ATC01 | C7: Producción / Consumo intermedio | D7: Consumo intermedio de mercado | E7: 2 | F7: P2 | G7: Consumo intermedio | H7: 6 | I7: 1
A8: P22 | B8: ATC01 | C8: Producción / Consumo intermedio | D8: Consumo intermedio para uso final propio | E8: 2 | F8: P2 | G8: Consumo intermedio | H8: 7 | I8: 2
A9: P23 | B9: ATC01 | C9: Producción / Consumo intermedio | D9: Consumo intermedio no de mercado | E9: 2 | F9: P2 | G9: Consumo intermedio | H9: 8 | I9: 3
A10: Pa31 | B10: ATC06 | C10: Gasto de consumo final | D10: Gasto de consumo final de los hogares | E10: 3 | F10: P3 | G10: Gasto de consumo final | H10: 9 | I10: 9
A11: Pb30 | B11: ATC06 | C11: Consumo final | D11: Gasto de consumo ISFLH | E11: 3 | F11: P3 | G11: Gasto de consumo final | H11: 10 | I11: 9
A12: Pb31 | B12: ATC06 | C12: Consumo final | D12: Gasto de consumo individual ISFLSH | E12: 3 | F12: P3 | G12: Gasto de consumo final | H12: 11 | I12: 9
A13: Pb32 | B13: ATC06 | C13: Consumo final | D13: Gasto de consumo colectivo ISFLSH | E13: 3 | F13: P3 | G13: Gasto de consumo final | H13: 12 | I13: 9
A14: Pc30 | B14: ATC06 | C14: Consumo final | D14: Gasto de consumo de gobierno | E14: 3 | F14: P3 | G14: Gasto de consumo final
A15: Pc31 | B15: ATC06 | C15: Consumo final | D15: Gasto de consumo individual de gobierno | E15: 3 | F15: P3 | G15: Gasto de consumo final | H15: 13 | I15: 9
A16: Pc32 | B16: ATC06 | C16: Consumo final | D16: Gasto de consumo colectivo de gobierno | E16: 3 | F16: P3 | G16: Gasto de consumo final | H16: 14 | I16: 9
A17: P41 | B17: ATC06 | C17: Consumo final | D17: Consumo individual efectivo | E17: 4 | F17: P4 | G17: Consumo final efectivo | H17: 15 | I17: 9
A18: P42 | B18: ATC06 | C18: Consumo final | D18: Consumo colectivo efectivo | E18: 4 | F18: P4 | G18: Consumo final efectivo | H18: 16 | I18: 9
A19: P51b | B19: ATC07 | C19: Consumo final | D19: Formación bruta de capital fijo | E19: 5 | F19: P5 | G19: Formación de capital | H19: 17 | I19: 10
A20: P51c | B20: ATC07 | C20: Consumo final | D20: Consumo de capital fijo | E20: 5 | F20: P5 | G20: Formación de capital | H20: 18 | I20: 10
A21: P52 | B21: ATC07 | C21: Consumo final | D21: Variación de existencias | E21: 5 | F21: P5 | G21: Formación de capital | H21: 19 | I21: 10
A22: P53 | B22: ATC07 | C22: Consumo final | D22: Adquisiciones menos disposiciones de objetos valiosos | E22: 5 | F22: P5 | G22: Formación de capital | H22: 20 | I22: 10
A23: P60 | B23: ATC02 | C23: Exportaciones / Importaciones | D23: Exportaciones de bienes y servicios | E23: 6 | F23: P6 | G23: Exportaciones de bienes y servicios | H23: 21 | I23: 4
A24: P61 | B24: ATC02 | C24: Exportaciones / Importaciones | D24: Exportaciones de bienes | E24: 6 | F24: P6 | G24: Exportaciones de bienes y servicios | H24: 22 | I24: 4
A25: P62 | B25: ATC02 | C25: Exportaciones / Importaciones | D25: Exportaciones de servicios | E25: 6 | F25: P6 | G25: Exportaciones de bienes y servicios | H25: 23 | I25: 4
